Workbook

Sheet KD Mappings
A1: KD ID | B1: KD | C1: KAs (mapping) | D1: Human winner agrees with AI | E1: All human differ (4) | F1: All 4 differ | G1: Sara KAs | H1: Sara Reasonings | I1: Valtteri KAs | J1: Valtteri Reasonings | K1: Paul Kas | L1: Paul Reasonings | O1: Same S&V | P1: Intersected S&V | Q1: Same AI & V | R1: Intersected AI & V | S1: Same AI&S | T1: Intersected AI & S | U1: Same P & S | V1: Intersected P&S | W1: Same P & AI | X1: Intersecter P&AI | Y1: Same P&V | Z1: Intersected P&V | AA1: # of same AI&S | AB1: # of intersected AI & S
A2: K0640 | B2: Knowledge of the organizational cybersecurity workforce | C2: 7 | D2: 1 | G2: ='Sara Mappings'!C2 -> 7 | H2: =IF('Sara Mappings'!D2=0,"",'Sara Mappings'!D2) | I2: ='Valtteri Mappings'!C2 -> 7 | J2: =IF('Valtteri Mappings'!D2=0,"",'Valtteri Mappings'!D2) | K2: ='Paul Mappings'!C2 -> 7.6 | L2: =IF('Paul Mappings'!D2=0,"",'Paul Mappings'!D2) -> 7 clear but social engineering, awareness and understanding also | O2: =IF(SUBSTITUTE(G2," ","") = SUBSTITUTE(I2," ",""), 1, 0) -> 1 | P2: {=SUMPRODUCT(--(ISNUMBER(SEARCH({"0";"1";"2";"3";"4";"5";"6";"7";"8"},SUBSTITUTE(G2," ",""))) * ISNUMBER(SEARCH({"0";"1";"2";"3";"4";"5";"6";"7";"8"},SUBSTITUTE(I2," ","")))))} -> 1 | Q2: =IF(SUBSTITUTE(C2," ","") = SUBSTITUTE(I2," ",""), 1, 0) -> 1 | R2: {=SUMPRODUCT(--(ISNUMBER(SEARCH({"0";"1";"2";"3";"4";"5";"6";"7";"8"},SUBSTITUTE(C2," ",""))) * ISNUMBER(SEARCH({"0";"1";"2";"3";"4";"5";"6";"7";"8"},SUBSTITUTE(I2," ","")))))} -> 1 | S2: =IF(SUBSTITUTE(C2," ","") = SUBSTITUTE(G2," ",""), 1, 0) -> 1 | T2: {=SUMPRODUCT(--(ISNUMBER(SEARCH({"0";"1";"2";"3";"4";"5";"6";"7";"8"},SUBSTITUTE(C2," ",""))) * ISNUMBER(SEARCH({"0";"1";"2";"3";"4";"5";"6";"7";"8"},SUBSTITUTE(G2," ","")))))} -> 1 | U2: =IF(SUBSTITUTE(K2," ","") = SUBSTITUTE(G2," ",""), 1, 0) -> 0 | V2: {=SUMPRODUCT(--(ISNUMBER(SEARCH({"0";"1";"2";"3";"4";"5";"6";"7";"8"},SUBSTITUTE(K2," ",""))) * ISNUMBER(SEARCH({"0";"1";"2";"3";"4";"5";"6";"7";"8"},SUBSTITUTE(G2," ","")))))} -> 1 | W2: =IF(SUBSTITUTE(K2," ","") = SUBSTITUTE(C2," ",""), 1, 0) -> 0 | X2: {=SUMPRODUCT(--(ISNUMBER(SEARCH({"0";"1";"2";"3";"4";"5";"6";"7";"8"},SUBSTITUTE(K2," ",""))) * ISNUMBER(SEARCH({"0";"1";"2";"3";"4";"5";"6";"7";"8"},SUBSTITUTE(C2," ","")))))} -> 1 | Y2: =IF(SUBSTITUTE(K2," ","") = SUBSTITUTE(I2," ",""), 1, 0) -> 0 | Z2: {=SUMPRODUCT(--(ISNUMBER(SEARCH({"0";"1";"2";"3";"4";"5";"6";"7";"8"},SUBSTITUTE(K2," ",""))) * ISNUMBER(SEARCH({"0";"1";"2";"3";"4";"5";"6";"7";"8"},SUBSTITUTE(I2," ","")))))} -> 1 | AA2: =SUM(S2:S52) -> 17 | AB2: =SUM(T2:T52) -> 31
A3: K0643 | B3: Knowledge of virtual learning environments | C3: 0 | D3: 1 | G3: ='Sara Mappings'!C3 -> 0 | H3: =IF('Sara Mappings'!D3=0,"",'Sara Mappings'!D3) -> pedagogy | I3: ='Valtteri Mappings'!C3 -> 6 | J3: =IF('Valtteri Mappings'!D3=0,"",'Valtteri Mappings'!D3) | K3: ='Paul Mappings'!C3 -> 0 | L3: =IF('Paul Mappings'!D3=0,"",'Paul Mappings'!D3) | O3: =IF(SUBSTITUTE(G3," ","") = SUBSTITUTE(I3," ",""), 1, 0) -> 0 | P3: {=SUMPRODUCT(--(ISNUMBER(SEARCH({"0";"1";"2";"3";"4";"5";"6";"7";"8"},SUBSTITUTE(G3," ",""))) * ISNUMBER(SEARCH({"0";"1";"2";"3";"4";"5";"6";"7";"8"},SUBSTITUTE(I3," ","")))))} -> 0 | Q3: =IF(SUBSTITUTE(C3," ","") = SUBSTITUTE(I3," ",""), 1, 0) -> 0 | R3: {=SUMPRODUCT(--(ISNUMBER(SEARCH({"0";"1";"2";"3";"4";"5";"6";"7";"8"},SUBSTITUTE(C3," ",""))) * ISNUMBER(SEARCH({"0";"1";"2";"3";"4";"5";"6";"7";"8"},SUBSTITUTE(I3," ","")))))} -> 0 | S3: =IF(SUBSTITUTE(C3," ","") = SUBSTITUTE(G3," ",""), 1, 0) -> 1 | T3: {=SUMPRODUCT(--(ISNUMBER(SEARCH({"0";"1";"2";"3";"4";"5";"6";"7";"8"},SUBSTITUTE(C3," ",""))) * ISNUMBER(SEARCH({"0";"1";"2";"3";"4";"5";"6";"7";"8"},SUBSTITUTE(G3," ","")))))} -> 1 | U3: =IF(SUBSTITUTE(K3," ","") = SUBSTITUTE(G3," ",""), 1, 0) -> 1 | V3: {=SUMPRODUCT(--(ISNUMBER(SEARCH({"0";"1";"2";"3";"4";"5";"6";"7";"8"},SUBSTITUTE(K3," ",""))) * ISNUMBER(SEARCH({"0";"1";"2";"3";"4";"5";"6";"7";"8"},SUBSTITUTE(G3," ","")))))} -> 1 | W3: =IF(SUBSTITUTE(K3," ","") = SUBSTITUTE(C3," ",""), 1, 0) -> 1 | X3: {=SUMPRODUCT(--(ISNUMBER(SEARCH({"0";"1";"2";"3";"4";"5";"6";"7";"8"},SUBSTITUTE(K3," ",""))) * ISNUMBER(SEARCH({"0";"1";"2";"3";"4";"5";"6";"7";"8"},SUBSTITUTE(C3," ","")))))} -> 1 | Y3: =IF(SUBSTITUTE(K3," ","") = SUBSTITUTE(I3," ",""), 1, 0) -> 0 | Z3: {=SUMPRODUCT(--(ISNUMBER(SEARCH({"0";"1";"2";"3";"4";"5";"6";"7";"8"},SUBSTITUTE(K3," ",""))) * ISNUMBER(SEARCH({"0";"1";"2";"3";"4";"5";"6";"7";"8"},SUBSTITUTE(I3," ","")))))} -> 0 | AA3: =AA2/50 -> 0.34 | AB3: =AB2/50 -> 0.62
A4: K0645 | B4: Knowledge of standard operating procedures (SOPs) | C4: 7 | D4: 1 | G4: ='Sara Mappings'!C4 -> 7 | H4: =IF('Sara Mappings'!D4=0,"",'Sara Mappings'!D4) -> A standard operating procedure is a set of step-by-step instructions compiled by an organization to help workers carry out routine operations. (This KD is not directly relating to the cybersecurity, so it can also be 0) | I4: ='Valtteri Mappings'!C4 -> 7 | J4: =IF('Valtteri Mappings'!D4=0,"",'Valtteri Mappings'!D4) | K4: ='Paul Mappings'!C4 -> 7.5 | L4: =IF('Paul Mappings'!D4=0,"",'Paul Mappings'!D4) -> Clear standardization (of procedures here) topic missing in the KAs | O4: =IF(SUBSTITUTE(G4," ","") = SUBSTITUTE(I4," ",""), 1, 0) -> 1 | P4: {=SUMPRODUCT(--(ISNUMBER(SEARCH({"0";"1";"2";"3";"4";"5";"6";"7";"8"},SUBSTITUTE(G4," ",""))) * ISNUMBER(SEARCH({"0";"1";"2";"3";"4";"5";"6";"7";"8"},SUBSTITUTE(I4," ","")))))} -> 1 | Q4: =IF(SUBSTITUTE(C4," ","") = SUBSTITUTE(I4," ",""), 1, 0) -> 1 | R4: {=SUMPRODUCT(--(ISNUMBER(SEARCH({"0";"1";"2";"3";"4";"5";"6";"7";"8"},SUBSTITUTE(C4," ",""))) * ISNUMBER(SEARCH({"0";"1";"2";"3";"4";"5";"6";"7";"8"},SUBSTITUTE(I4," ","")))))} -> 1 | S4: =IF(SUBSTITUTE(C4," ","") = SUBSTITUTE(G4," ",""), 1, 0) -> 1 | T4: {=SUMPRODUCT(--(ISNUMBER(SEARCH({"0";"1";"2";"3";"4";"5";"6";"7";"8"},SUBSTITUTE(C4," ",""))) * ISNUMBER(SEARCH({"0";"1";"2";"3";"4";"5";"6";"7";"8"},SUBSTITUTE(G4," ","")))))} -> 1 | U4: =IF(SUBSTITUTE(K4," ","") = SUBSTITUTE(G4," ",""), 1, 0) -> 0 | V4: {=SUMPRODUCT(--(ISNUMBER(SEARCH({"0";"1";"2";"3";"4";"5";"6";"7";"8"},SUBSTITUTE(K4," ",""))) * ISNUMBER(SEARCH({"0";"1";"2";"3";"4";"5";"6";"7";"8"},SUBSTITUTE(G4," ","")))))} -> 1 | W4: =IF(SUBSTITUTE(K4," ","") = SUBSTITUTE(C4," ",""), 1, 0) -> 0 | X4: {=SUMPRODUCT(--(ISNUMBER(SEARCH({"0";"1";"2";"3";"4";"5";"6";"7";"8"},SUBSTITUTE(K4," ",""))) * ISNUMBER(SEARCH({"0";"1";"2";"3";"4";"5";"6";"7";"8"},SUBSTITUTE(C4," ","")))))} -> 1 | Y4: =IF(SUBSTITUTE(K4," ","") = SUBSTITUTE(I4," ",""), 1, 0) -> 0 | Z4: {=SUMPRODUCT(--(ISNUMBER(SEARCH({"0";"1";"2";"3";"4";"5";"6";"7";"8"},SUBSTITUTE(K4," ",""))) * ISNUMBER(SEARCH({"0";"1";"2";"3";"4";"5";"6";"7";"8"},SUBSTITUTE(I4," ","")))))} -> 1 | AA4: # of same AI&V | AB4: # of intersected AI & V
A5: K0662 | B5: Knowledge of systems security engineering | C5: 5 | D5: 1 | G5: ='Sara Mappings'!C5 -> 4 | H5: =IF('Sara Mappings'!D5=0,"",'Sara Mappings'!D5) -> Systems fall under KA-4 | I5: ='Valtteri Mappings'!C5 -> 5 | J5: =IF('Valtteri Mappings'!D5=0,"",'Valtteri Mappings'!D5) | K5: ='Paul Mappings'!C5 -> 5 | L5: =IF('Paul Mappings'!D5=0,"",'Paul Mappings'!D5) | O5: =IF(SUBSTITUTE(G5," ","") = SUBSTITUTE(I5," ",""), 1, 0) -> 0 | P5: {=SUMPRODUCT(--(ISNUMBER(SEARCH({"0";"1";"2";"3";"4";"5";"6";"7";"8"},SUBSTITUTE(G5," ",""))) * ISNUMBER(SEARCH({"0";"1";"2";"3";"4";"5";"6";"7";"8"},SUBSTITUTE(I5," ","")))))} -> 0 | Q5: =IF(SUBSTITUTE(C5," ","") = SUBSTITUTE(I5," ",""), 1, 0) -> 1 | R5: {=SUMPRODUCT(--(ISNUMBER(SEARCH({"0";"1";"2";"3";"4";"5";"6";"7";"8"},SUBSTITUTE(C5," ",""))) * ISNUMBER(SEARCH({"0";"1";"2";"3";"4";"5";"6";"7";"8"},SUBSTITUTE(I5," ","")))))} -> 1 | S5: =IF(SUBSTITUTE(C5," ","") = SUBSTITUTE(G5," ",""), 1, 0) -> 0 | T5: {=SUMPRODUCT(--(ISNUMBER(SEARCH({"0";"1";"2";"3";"4";"5";"6";"7";"8"},SUBSTITUTE(C5," ",""))) * ISNUMBER(SEARCH({"0";"1";"2";"3";"4";"5";"6";"7";"8"},SUBSTITUTE(G5," ","")))))} -> 0 | U5: =IF(SUBSTITUTE(K5," ","") = SUBSTITUTE(G5," ",""), 1, 0) -> 0 | V5: {=SUMPRODUCT(--(ISNUMBER(SEARCH({"0";"1";"2";"3";"4";"5";"6";"7";"8"},SUBSTITUTE(K5," ",""))) * ISNUMBER(SEARCH({"0";"1";"2";"3";"4";"5";"6";"7";"8"},SUBSTITUTE(G5," ","")))))} -> 0 | W5: =IF(SUBSTITUTE(K5," ","") = SUBSTITUTE(C5," ",""), 1, 0) -> 1 | X5: {=SUMPRODUCT(--(ISNUMBER(SEARCH({"0";"1";"2";"3";"4";"5";"6";"7";"8"},SUBSTITUTE(K5," ",""))) * ISNUMBER(SEARCH({"0";"1";"2";"3";"4";"5";"6";"7";"8"},SUBSTITUTE(C5," ","")))))} -> 1 | Y5: =IF(SUBSTITUTE(K5," ","") = SUBSTITUTE(I5," ",""), 1, 0) -> 1 | Z5: {=SUMPRODUCT(--(ISNUMBER(SEARCH({"0";"1";"2";"3";"4";"5";"6";"7";"8"},SUBSTITUTE(K5," ",""))) * ISNUMBER(SEARCH({"0";"1";"2";"3";"4";"5";"6";"7";"8"},SUBSTITUTE(I5," ","")))))} -> 1 | AA5: =SUM(Q2:Q51) -> 21 | AB5: =SUM(R2:R51) -> 39
A6: K0706 | B6: Knowledge of database schema capabilities and applications | C6: 0 | D6: 1 | G6: ='Sara Mappings'!C6 -> 0 | H6: =IF('Sara Mappings'!D6=0,"",'Sara Mappings'!D6) | I6: ='Valtteri Mappings'!C6 -> 0 | J6: =IF('Valtteri Mappings'!D6=0,"",'Valtteri Mappings'!D6) | K6: ='Paul Mappings'!C6 -> 1.2 | L6: =IF('Paul Mappings'!D6=0,"",'Paul Mappings'!D6) -> implementation issues for 2 | O6: =IF(SUBSTITUTE(G6," ","") = SUBSTITUTE(I6," ",""), 1, 0) -> 1 | P6: {=SUMPRODUCT(--(ISNUMBER(SEARCH({"0";"1";"2";"3";"4";"5";"6";"7";"8"},SUBSTITUTE(G6," ",""))) * ISNUMBER(SEARCH({"0";"1";"2";"3";"4";"5";"6";"7";"8"},SUBSTITUTE(I6," ","")))))} -> 1 | Q6: =IF(SUBSTITUTE(C6," ","") = SUBSTITUTE(I6," ",""), 1, 0) -> 1 | R6: {=SUMPRODUCT(--(ISNUMBER(SEARCH({"0";"1";"2";"3";"4";"5";"6";"7";"8"},SUBSTITUTE(C6," ",""))) * ISNUMBER(SEARCH({"0";"1";"2";"3";"4";"5";"6";"7";"8"},SUBSTITUTE(I6," ","")))))} -> 1 | S6: =IF(SUBSTITUTE(C6," ","") = SUBSTITUTE(G6," ",""), 1, 0) -> 1 | T6: {=SUMPRODUCT(--(ISNUMBER(SEARCH({"0";"1";"2";"3";"4";"5";"6";"7";"8"},SUBSTITUTE(C6," ",""))) * ISNUMBER(SEARCH({"0";"1";"2";"3";"4";"5";"6";"7";"8"},SUBSTITUTE(G6," ","")))))} -> 1 | U6: =IF(SUBSTITUTE(K6," ","") = SUBSTITUTE(G6," ",""), 1, 0) -> 0 | V6: {=SUMPRODUCT(--(ISNUMBER(SEARCH({"0";"1";"2";"3";"4";"5";"6";"7";"8"},SUBSTITUTE(K6," ",""))) * ISNUMBER(SEARCH({"0";"1";"2";"3";"4";"5";"6";"7";"8"},SUBSTITUTE(G6," ","")))))} -> 0 | W6: =IF(SUBSTITUTE(K6," ","") = SUBSTITUTE(C6," ",""), 1, 0) -> 0 | X6: {=SUMPRODUCT(--(ISNUMBER(SEARCH({"0";"1";"2";"3";"4";"5";"6";"7";"8"},SUBSTITUTE(K6," ",""))) * ISNUMBER(SEARCH({"0";"1";"2";"3";"4";"5";"6";"7";"8"},SUBSTITUTE(C6," ","")))))} -> 0 | Y6: =IF(SUBSTITUTE(K6," ","") = SUBSTITUTE(I6," ",""), 1, 0) -> 0 | Z6: {=SUMPRODUCT(--(ISNUMBER(SEARCH({"0";"1";"2";"3";"4";"5";"6";"7";"8"},SUBSTITUTE(K6," ",""))) * ISNUMBER(SEARCH({"0";"1";"2";"3";"4";"5";"6";"7";"8"},SUBSTITUTE(I6," ","")))))} -> 0 | AA6: =AA5/50 -> 0.42 | AB6: =AB5/50 -> 0.78
A7: K0710 | B7: Knowledge of enterprise cybersecurity architecture principles and practices | C7: 5, 7 | D7: 1 | G7: ='Sara Mappings'!C7 -> 7 | H7: =IF('Sara Mappings'!D7=0,"",'Sara Mappings'!D7) | I7: ='Valtteri Mappings'!C7 -> 5, 7 | J7: =IF('Valtteri Mappings'!D7=0,"",'Valtteri Mappings'!D7) | K7: ='Paul Mappings'!C7 -> 7 | L7: =IF('Paul Mappings'!D7=0,"",'Paul Mappings'!D7) -> Could be 4 also, depending on the architecture level | O7: =IF(SUBSTITUTE(G7," ","") = SUBSTITUTE(I7," ",""), 1, 0) -> 0 | P7: {=SUMPRODUCT(--(ISNUMBER(SEARCH({"0";"1";"2";"3";"4";"5";"6";"7";"8"},SUBSTITUTE(G7," ",""))) * ISNUMBER(SEARCH({"0";"1";"2";"3";"4";"5";"6";"7";"8"},SUBSTITUTE(I7," ","")))))} -> 1 | Q7: =IF(SUBSTITUTE(C7," ","") = SUBSTITUTE(I7," ",""), 1, 0) -> 1 | R7: {=SUMPRODUCT(--(ISNUMBER(SEARCH({"0";"1";"2";"3";"4";"5";"6";"7";"8"},SUBSTITUTE(C7," ",""))) * ISNUMBER(SEARCH({"0";"1";"2";"3";"4";"5";"6";"7";"8"},SUBSTITUTE(I7," ","")))))} -> 2 | S7: =IF(SUBSTITUTE(C7," ","") = SUBSTITUTE(G7," ",""), 1, 0) -> 0 | T7: {=SUMPRODUCT(--(ISNUMBER(SEARCH({"0";"1";"2";"3";"4";"5";"6";"7";"8"},SUBSTITUTE(C7," ",""))) * ISNUMBER(SEARCH({"0";"1";"2";"3";"4";"5";"6";"7";"8"},SUBSTITUTE(G7," ","")))))} -> 1 | U7: =IF(SUBSTITUTE(K7," ","") = SUBSTITUTE(G7," ",""), 1, 0) -> 1 | V7: {=SUMPRODUCT(--(ISNUMBER(SEARCH({"0";"1";"2";"3";"4";"5";"6";"7";"8"},SUBSTITUTE(K7," ",""))) * ISNUMBER(SEARCH({"0";"1";"2";"3";"4";"5";"6";"7";"8"},SUBSTITUTE(G7," ","")))))} -> 1 | W7: =IF(SUBSTITUTE(K7," ","") = SUBSTITUTE(C7," ",""), 1, 0) -> 0 | X7: {=SUMPRODUCT(--(ISNUMBER(SEARCH({"0";"1";"2";"3";"4";"5";"6";"7";"8"},SUBSTITUTE(K7," ",""))) * ISNUMBER(SEARCH({"0";"1";"2";"3";"4";"5";"6";"7";"8"},SUBSTITUTE(C7," ","")))))} -> 1 | Y7: =IF(SUBSTITUTE(K7," ","") = SUBSTITUTE(I7," ",""), 1, 0) -> 0 | Z7: {=SUMPRODUCT(--(ISNUMBER(SEARCH({"0";"1";"2";"3";"4";"5";"6";"7";"8"},SUBSTITUTE(K7," ",""))) * ISNUMBER(SEARCH({"0";"1";"2";"3";"4";"5";"6";"7";"8"},SUBSTITUTE(I7," ","")))))} -> 1 | AA7: # of same S&V | AB7: # of intersected S & V
A8: K0713 | B8: Knowledge of Wide Area Networks (WAN) | C8: 0 | D8: 0 | G8: ='Sara Mappings'!C8 -> 4 | H8: =IF('Sara Mappings'!D8=0,"",'Sara Mappings'!D8) | I8: ='Valtteri Mappings'!C8 -> 4 | J8: =IF('Valtteri Mappings'!D8=0,"",'Valtteri Mappings'!D8) | K8: ='Paul Mappings'!C8 -> 4,0,1 | L8: =IF('Paul Mappings'!D8=0,"",'Paul Mappings'!D8) -> 1 is a low level interpretation (data flow) | O8: =IF(SUBSTITUTE(G8," ","") = SUBSTITUTE(I8," ",""), 1, 0) -> 1 | P8: {=SUMPRODUCT(--(ISNUMBER(SEARCH({"0";"1";"2";"3";"4";"5";"6";"7";"8"},SUBSTITUTE(G8," ",""))) * ISNUMBER(SEARCH({"0";"1";"2";"3";"4";"5";"6";"7";"8"},SUBSTITUTE(I8," ","")))))} -> 1 | Q8: =IF(SUBSTITUTE(C8," ","") = SUBSTITUTE(I8," ",""), 1, 0) -> 0 | R8: {=SUMPRODUCT(--(ISNUMBER(SEARCH({"0";"1";"2";"3";"4";"5";"6";"7";"8"},SUBSTITUTE(C8," ",""))) * ISNUMBER(SEARCH({"0";"1";"2";"3";"4";"5";"6";"7";"8"},SUBSTITUTE(I8," ","")))))} -> 0 | S8: =IF(SUBSTITUTE(C8," ","") = SUBSTITUTE(G8," ",""), 1, 0) -> 0 | T8: {=SUMPRODUCT(--(ISNUMBER(SEARCH({"0";"1";"2";"3";"4";"5";"6";"7";"8"},SUBSTITUTE(C8," ",""))) * ISNUMBER(SEARCH({"0";"1";"2";"3";"4";"5";"6";"7";"8"},SUBSTITUTE(G8," ","")))))} -> 0 | U8: =IF(SUBSTITUTE(K8," ","") = SUBSTITUTE(G8," ",""), 1, 0) -> 0 | V8: {=SUMPRODUCT(--(ISNUMBER(SEARCH({"0";"1";"2";"3";"4";"5";"6";"7";"8"},SUBSTITUTE(K8," ",""))) * ISNUMBER(SEARCH({"0";"1";"2";"3";"4";"5";"6";"7";"8"},SUBSTITUTE(G8," ","")))))} -> 1 | W8: =IF(SUBSTITUTE(K8," ","") = SUBSTITUTE(C8," ",""), 1, 0) -> 0 | X8: {=SUMPRODUCT(--(ISNUMBER(SEARCH({"0";"1";"2";"3";"4";"5";"6";"7";"8"},SUBSTITUTE(K8," ",""))) * ISNUMBER(SEARCH({"0";"1";"2";"3";"4";"5";"6";"7";"8"},SUBSTITUTE(C8," ","")))))} -> 1 | Y8: =IF(SUBSTITUTE(K8," ","") = SUBSTITUTE(I8," ",""), 1, 0) -> 0 | Z8: {=SUMPRODUCT(--(ISNUMBER(SEARCH({"0";"1";"2";"3";"4";"5";"6";"7";"8"},SUBSTITUTE(K8," ",""))) * ISNUMBER(SEARCH({"0";"1";"2";"3";"4";"5";"6";"7";"8"},SUBSTITUTE(I8," ","")))))} -> 1 | AA8: =SUM(O2:O51) -> 25 | AB8: =SUM(P2:P51) -> 26
A9: K0719 | B9: Knowledge of human-computer interaction (HCI) principles and practices | C9: 0, 6 | D9: 1 | G9: ='Sara Mappings'!C9 -> 0 | H9: =IF('Sara Mappings'!D9=0,"",'Sara Mappings'!D9) -> Falls under software development (Computer Science) | I9: ='Valtteri Mappings'!C9 -> 0 | J9: =IF('Valtteri Mappings'!D9=0,"",'Valtteri Mappings'!D9) | K9: ='Paul Mappings'!C9 -> 6 | L9: =IF('Paul Mappings'!D9=0,"",'Paul Mappings'!D9) | O9: =IF(SUBSTITUTE(G9," ","") = SUBSTITUTE(I9," ",""), 1, 0) -> 1 | P9: {=SUMPRODUCT(--(ISNUMBER(SEARCH({"0";"1";"2";"3";"4";"5";"6";"7";"8"},SUBSTITUTE(G9," ",""))) * ISNUMBER(SEARCH({"0";"1";"2";"3";"4";"5";"6";"7";"8"},SUBSTITUTE(I9," ","")))))} -> 1 | Q9: =IF(SUBSTITUTE(C9," ","") = SUBSTITUTE(I9," ",""), 1, 0) -> 0 | R9: {=SUMPRODUCT(--(ISNUMBER(SEARCH({"0";"1";"2";"3";"4";"5";"6";"7";"8"},SUBSTITUTE(C9," ",""))) * ISNUMBER(SEARCH({"0";"1";"2";"3";"4";"5";"6";"7";"8"},SUBSTITUTE(I9," ","")))))} -> 1 | S9: =IF(SUBSTITUTE(C9," ","") = SUBSTITUTE(G9," ",""), 1, 0) -> 0 | T9: {=SUMPRODUCT(--(ISNUMBER(SEARCH({"0";"1";"2";"3";"4";"5";"6";"7";"8"},SUBSTITUTE(C9," ",""))) * ISNUMBER(SEARCH({"0";"1";"2";"3";"4";"5";"6";"7";"8"},SUBSTITUTE(G9," ","")))))} -> 1 | U9: =IF(SUBSTITUTE(K9," ","") = SUBSTITUTE(G9," ",""), 1, 0) -> 0 | V9: {=SUMPRODUCT(--(ISNUMBER(SEARCH({"0";"1";"2";"3";"4";"5";"6";"7";"8"},SUBSTITUTE(K9," ",""))) * ISNUMBER(SEARCH({"0";"1";"2";"3";"4";"5";"6";"7";"8"},SUBSTITUTE(G9," ","")))))} -> 0 | W9: =IF(SUBSTITUTE(K9," ","") = SUBSTITUTE(C9," ",""), 1, 0) -> 0 | X9: {=SUMPRODUCT(--(ISNUMBER(SEARCH({"0";"1";"2";"3";"4";"5";"6";"7";"8"},SUBSTITUTE(K9," ",""))) * ISNUMBER(SEARCH({"0";"1";"2";"3";"4";"5";"6";"7";"8"},SUBSTITUTE(C9," ","")))))} -> 1 | Y9: =IF(SUBSTITUTE(K9," ","") = SUBSTITUTE(I9," ",""), 1, 0) -> 0 | Z9: {=SUMPRODUCT(--(ISNUMBER(SEARCH({"0";"1";"2";"3";"4";"5";"6";"7";"8"},SUBSTITUTE(K9," ",""))) * ISNUMBER(SEARCH({"0";"1";"2";"3";"4";"5";"6";"7";"8"},SUBSTITUTE(I9," ","")))))} -> 0 | AA9: =AA8/50 -> 0.5 | AB9: =AB8/50 -> 0.52
A10: K0732 | B10: Knowledge of intrusion detection tools and techniques | C10: 5 | D10: 0 | G10: ='Sara Mappings'!C10 -> 4 | H10: =IF('Sara Mappings'!D10=0,"",'Sara Mappings'!D10) -> Network Defense | I10: ='Valtteri Mappings'!C10 -> 5 | J10: =IF('Valtteri Mappings'!D10=0,"",'Valtteri Mappings'!D10) | K10: ='Paul Mappings'!C10 -> 4 | L10: =IF('Paul Mappings'!D10=0,"",'Paul Mappings'!D10) -> Seems that a separate network security KA is "missing" but IDS included in 4. 0,5,2,1,3 also seem reasonable to me here. | O10: =IF(SUBSTITUTE(G10," ","") = SUBSTITUTE(I10," ",""), 1, 0) -> 0 | P10: {=SUMPRODUCT(--(ISNUMBER(SEARCH({"0";"1";"2";"3";"4";"5";"6";"7";"8"},SUBSTITUTE(G10," ",""))) * ISNUMBER(SEARCH({"0";"1";"2";"3";"4";"5";"6";"7";"8"},SUBSTITUTE(I10," ","")))))} -> 0 | Q10: =IF(SUBSTITUTE(C10," ","") = SUBSTITUTE(I10," ",""), 1, 0) -> 1 | R10: {=SUMPRODUCT(--(ISNUMBER(SEARCH({"0";"1";"2";"3";"4";"5";"6";"7";"8"},SUBSTITUTE(C10," ",""))) * ISNUMBER(SEARCH({"0";"1";"2";"3";"4";"5";"6";"7";"8"},SUBSTITUTE(I10," ","")))))} -> 1 | S10: =IF(SUBSTITUTE(C10," ","") = SUBSTITUTE(G10," ",""), 1, 0) -> 0 | T10: {=SUMPRODUCT(--(ISNUMBER(SEARCH({"0";"1";"2";"3";"4";"5";"6";"7";"8"},SUBSTITUTE(C10," ",""))) * ISNUMBER(SEARCH({"0";"1";"2";"3";"4";"5";"6";"7";"8"},SUBSTITUTE(G10," ","")))))} -> 0 | U10: =IF(SUBSTITUTE(K10," ","") = SUBSTITUTE(G10," ",""), 1, 0) -> 1 | V10: {=SUMPRODUCT(--(ISNUMBER(SEARCH({"0";"1";"2";"3";"4";"5";"6";"7";"8"},SUBSTITUTE(K10," ",""))) * ISNUMBER(SEARCH({"0";"1";"2";"3";"4";"5";"6";"7";"8"},SUBSTITUTE(G10," ","")))))} -> 1 | W10: =IF(SUBSTITUTE(K10," ","") = SUBSTITUTE(C10," ",""), 1, 0) -> 0 | X10: {=SUMPRODUCT(--(ISNUMBER(SEARCH({"0";"1";"2";"3";"4";"5";"6";"7";"8"},SUBSTITUTE(K10," ",""))) * ISNUMBER(SEARCH({"0";"1";"2";"3";"4";"5";"6";"7";"8"},SUBSTITUTE(C10," ","")))))} -> 0 | Y10: =IF(SUBSTITUTE(K10," ","") = SUBSTITUTE(I10," ",""), 1, 0) -> 0 | Z10: {=SUMPRODUCT(--(ISNUMBER(SEARCH({"0";"1";"2";"3";"4";"5";"6";"7";"8"},SUBSTITUTE(K10," ",""))) * ISNUMBER(SEARCH({"0";"1";"2";"3";"4";"5";"6";"7";"8"},SUBSTITUTE(I10," ","")))))} -> 0 | AA10: # of same AI&P | AB10: # of intersected AI&P
A11: K0733 | B11: Knowledge of information technology (IT) architecture models and frameworks | C11: 0 | D11: 1 | G11: ='Sara Mappings'!C11 -> 0 | H11: =IF('Sara Mappings'!D11=0,"",'Sara Mappings'!D11) | I11: ='Valtteri Mappings'!C11 -> 0 | J11: =IF('Valtteri Mappings'!D11=0,"",'Valtteri Mappings'!D11) | K11: ='Paul Mappings'!C11 -> 5 | L11: =IF('Paul Mappings'!D11=0,"",'Paul Mappings'!D11) -> Bell-LaPadula …? 0 for Information Technology (wide topic) | O11: =IF(SUBSTITUTE(G11," ","") = SUBSTITUTE(I11," ",""), 1, 0) -> 1 | P11: {=SUMPRODUCT(--(ISNUMBER(SEARCH({"0";"1";"2";"3";"4";"5";"6";"7";"8"},SUBSTITUTE(G11," ",""))) * ISNUMBER(SEARCH({"0";"1";"2";"3";"4";"5";"6";"7";"8"},SUBSTITUTE(I11," ","")))))} -> 1 | Q11: =IF(SUBSTITUTE(C11," ","") = SUBSTITUTE(I11," ",""), 1, 0) -> 1 | R11: {=SUMPRODUCT(--(ISNUMBER(SEARCH({"0";"1";"2";"3";"4";"5";"6";"7";"8"},SUBSTITUTE(C11," ",""))) * ISNUMBER(SEARCH({"0";"1";"2";"3";"4";"5";"6";"7";"8"},SUBSTITUTE(I11," ","")))))} -> 1 | S11: =IF(SUBSTITUTE(C11," ","") = SUBSTITUTE(G11," ",""), 1, 0) -> 1 | T11: {=SUMPRODUCT(--(ISNUMBER(SEARCH({"0";"1";"2";"3";"4";"5";"6";"7";"8"},SUBSTITUTE(C11," ",""))) * ISNUMBER(SEARCH({"0";"1";"2";"3";"4";"5";"6";"7";"8"},SUBSTITUTE(G11," ","")))))} -> 1 | U11: =IF(SUBSTITUTE(K11," ","") = SUBSTITUTE(G11," ",""), 1, 0) -> 0 | V11: {=SUMPRODUCT(--(ISNUMBER(SEARCH({"0";"1";"2";"3";"4";"5";"6";"7";"8"},SUBSTITUTE(K11," ",""))) * ISNUMBER(SEARCH({"0";"1";"2";"3";"4";"5";"6";"7";"8"},SUBSTITUTE(G11," ","")))))} -> 0 | W11: =IF(SUBSTITUTE(K11," ","") = SUBSTITUTE(C11," ",""), 1, 0) -> 0 | X11: {=SUMPRODUCT(--(ISNUMBER(SEARCH({"0";"1";"2";"3";"4";"5";"6";"7";"8"},SUBSTITUTE(K11," ",""))) * ISNUMBER(SEARCH({"0";"1";"2";"3";"4";"5";"6";"7";"8"},SUBSTITUTE(C11," ","")))))} -> 0 | Y11: =IF(SUBSTITUTE(K11," ","") = SUBSTITUTE(I11," ",""), 1, 0) -> 0 | Z11: {=SUMPRODUCT(--(ISNUMBER(SEARCH({"0";"1";"2";"3";"4";"5";"6";"7";"8"},SUBSTITUTE(K11," ",""))) * ISNUMBER(SEARCH({"0";"1";"2";"3";"4";"5";"6";"7";"8"},SUBSTITUTE(I11," ","")))))} -> 0 | AA11: =SUM(W2:W51) -> 12 | AB11: {=SUMPRODUCT(--(X2:X51>=1))} -> 32
A12: K0757 | B12: Knowledge of system design tools and techniques | C12: 0 | D12: 0 | E12: 1 | F12: 0 | G12: ='Sara Mappings'!C12 -> 3 | H12: =IF('Sara Mappings'!D12=0,"",'Sara Mappings'!D12) -> Component Design (it can also be 0, as part of CS) | I12: ='Valtteri Mappings'!C12 -> 0 | J12: =IF('Valtteri Mappings'!D12=0,"",'Valtteri Mappings'!D12) | K12: ='Paul Mappings'!C12 -> 5 | L12: =IF('Paul Mappings'!D12=0,"",'Paul Mappings'!D12) | O12: =IF(SUBSTITUTE(G12," ","") = SUBSTITUTE(I12," ",""), 1, 0) -> 0 | P12: {=SUMPRODUCT(--(ISNUMBER(SEARCH({"0";"1";"2";"3";"4";"5";"6";"7";"8"},SUBSTITUTE(G12," ",""))) * ISNUMBER(SEARCH({"0";"1";"2";"3";"4";"5";"6";"7";"8"},SUBSTITUTE(I12," ","")))))} -> 0 | Q12: =IF(SUBSTITUTE(C12," ","") = SUBSTITUTE(I12," ",""), 1, 0) -> 1 | R12: {=SUMPRODUCT(--(ISNUMBER(SEARCH({"0";"1";"2";"3";"4";"5";"6";"7";"8"},SUBSTITUTE(C12," ",""))) * ISNUMBER(SEARCH({"0";"1";"2";"3";"4";"5";"6";"7";"8"},SUBSTITUTE(I12," ","")))))} -> 1 | S12: =IF(SUBSTITUTE(C12," ","") = SUBSTITUTE(G12," ",""), 1, 0) -> 0 | T12: {=SUMPRODUCT(--(ISNUMBER(SEARCH({"0";"1";"2";"3";"4";"5";"6";"7";"8"},SUBSTITUTE(C12," ",""))) * ISNUMBER(SEARCH({"0";"1";"2";"3";"4";"5";"6";"7";"8"},SUBSTITUTE(G12," ","")))))} -> 0 | U12: =IF(SUBSTITUTE(K12," ","") = SUBSTITUTE(G12," ",""), 1, 0) -> 0 | V12: {=SUMPRODUCT(--(ISNUMBER(SEARCH({"0";"1";"2";"3";"4";"5";"6";"7";"8"},SUBSTITUTE(K12," ",""))) * ISNUMBER(SEARCH({"0";"1";"2";"3";"4";"5";"6";"7";"8"},SUBSTITUTE(G12," ","")))))} -> 0 | W12: =IF(SUBSTITUTE(K12," ","") = SUBSTITUTE(C12," ",""), 1, 0) -> 0 | X12: {=SUMPRODUCT(--(ISNUMBER(SEARCH({"0";"1";"2";"3";"4";"5";"6";"7";"8"},SUBSTITUTE(K12," ",""))) * ISNUMBER(SEARCH({"0";"1";"2";"3";"4";"5";"6";"7";"8"},SUBSTITUTE(C12," ","")))))} -> 0 | Y12: =IF(SUBSTITUTE(K12," ","") = SUBSTITUTE(I12," ",""), 1, 0) -> 0 | Z12: {=SUMPRODUCT(--(ISNUMBER(SEARCH({"0";"1";"2";"3";"4";"5";"6";"7";"8"},SUBSTITUTE(K12," ",""))) * ISNUMBER(SEARCH({"0";"1";"2";"3";"4";"5";"6";"7";"8"},SUBSTITUTE(I12," ","")))))} -> 0 | AA12: =AA11/50 -> 0.24 | AB12: =AB11/50 -> 0.64
A13: K0765 | B13: Knowledge of software engineering principles and practices | C13: 0, 2 | D13: 1 | G13: ='Sara Mappings'!C13 -> 2 | H13: =IF('Sara Mappings'!D13=0,"",'Sara Mappings'!D13) -> it can also be 0, as part of CS | I13: ='Valtteri Mappings'!C13 -> 0 | J13: =IF('Valtteri Mappings'!D13=0,"",'Valtteri Mappings'!D13) | K13: ='Paul Mappings'!C13 -> 2 | L13: =IF('Paul Mappings'!D13=0,"",'Paul Mappings'!D13) | O13: =IF(SUBSTITUTE(G13," ","") = SUBSTITUTE(I13," ",""), 1, 0) -> 0 | P13: {=SUMPRODUCT(--(ISNUMBER(SEARCH({"0";"1";"2";"3";"4";"5";"6";"7";"8"},SUBSTITUTE(G13," ",""))) * ISNUMBER(SEARCH({"0";"1";"2";"3";"4";"5";"6";"7";"8"},SUBSTITUTE(I13," ","")))))} -> 0 | Q13: =IF(SUBSTITUTE(C13," ","") = SUBSTITUTE(I13," ",""), 1, 0) -> 0 | R13: {=SUMPRODUCT(--(ISNUMBER(SEARCH({"0";"1";"2";"3";"4";"5";"6";"7";"8"},SUBSTITUTE(C13," ",""))) * ISNUMBER(SEARCH({"0";"1";"2";"3";"4";"5";"6";"7";"8"},SUBSTITUTE(I13," ","")))))} -> 1 | S13: =IF(SUBSTITUTE(C13," ","") = SUBSTITUTE(G13," ",""), 1, 0) -> 0 | T13: {=SUMPRODUCT(--(ISNUMBER(SEARCH({"0";"1";"2";"3";"4";"5";"6";"7";"8"},SUBSTITUTE(C13," ",""))) * ISNUMBER(SEARCH({"0";"1";"2";"3";"4";"5";"6";"7";"8"},SUBSTITUTE(G13," ","")))))} -> 1 | U13: =IF(SUBSTITUTE(K13," ","") = SUBSTITUTE(G13," ",""), 1, 0) -> 1 | V13: {=SUMPRODUCT(--(ISNUMBER(SEARCH({"0";"1";"2";"3";"4";"5";"6";"7";"8"},SUBSTITUTE(K13," ",""))) * ISNUMBER(SEARCH({"0";"1";"2";"3";"4";"5";"6";"7";"8"},SUBSTITUTE(G13," ","")))))} -> 1 | W13: =IF(SUBSTITUTE(K13," ","") = SUBSTITUTE(C13," ",""), 1, 0) -> 0 | X13: {=SUMPRODUCT(--(ISNUMBER(SEARCH({"0";"1";"2";"3";"4";"5";"6";"7";"8"},SUBSTITUTE(K13," ",""))) * ISNUMBER(SEARCH({"0";"1";"2";"3";"4";"5";"6";"7";"8"},SUBSTITUTE(C13," ","")))))} -> 1 | Y13: =IF(SUBSTITUTE(K13," ","") = SUBSTITUTE(I13," ",""), 1, 0) -> 0 | Z13: {=SUMPRODUCT(--(ISNUMBER(SEARCH({"0";"1";"2";"3";"4";"5";"6";"7";"8"},SUBSTITUTE(K13," ",""))) * ISNUMBER(SEARCH({"0";"1";"2";"3";"4";"5";"6";"7";"8"},SUBSTITUTE(I13," ","")))))} -> 0 | AA13: # of same P&S | AB13: # of intersected P&S
A14: K0773 | B14: Knowledge of telecommunications principles and practices | C14: 0 | D14: 1 | G14: ='Sara Mappings'!C14 -> 0 | H14: =IF('Sara Mappings'!D14=0,"",'Sara Mappings'!D14) -> Communication and Networking | I14: ='Valtteri Mappings'!C14 -> 0 | J14: =IF('Valtteri Mappings'!D14=0,"",'Valtteri Mappings'!D14) | K14: ='Paul Mappings'!C14 -> 0 | L14: =IF('Paul Mappings'!D14=0,"",'Paul Mappings'!D14) -> o for communication and networking. No clear KA, 1,4 might also be appropriate | O14: =IF(SUBSTITUTE(G14," ","") = SUBSTITUTE(I14," ",""), 1, 0) -> 1 | P14: {=SUMPRODUCT(--(ISNUMBER(SEARCH({"0";"1";"2";"3";"4";"5";"6";"7";"8"},SUBSTITUTE(G14," ",""))) * ISNUMBER(SEARCH({"0";"1";"2";"3";"4";"5";"6";"7";"8"},SUBSTITUTE(I14," ","")))))} -> 1 | Q14: =IF(SUBSTITUTE(C14," ","") = SUBSTITUTE(I14," ",""), 1, 0) -> 1 | R14: {=SUMPRODUCT(--(ISNUMBER(SEARCH({"0";"1";"2";"3";"4";"5";"6";"7";"8"},SUBSTITUTE(C14," ",""))) * ISNUMBER(SEARCH({"0";"1";"2";"3";"4";"5";"6";"7";"8"},SUBSTITUTE(I14," ","")))))} -> 1 | S14: =IF(SUBSTITUTE(C14," ","") = SUBSTITUTE(G14," ",""), 1, 0) -> 1 | T14: {=SUMPRODUCT(--(ISNUMBER(SEARCH({"0";"1";"2";"3";"4";"5";"6";"7";"8"},SUBSTITUTE(C14," ",""))) * ISNUMBER(SEARCH({"0";"1";"2";"3";"4";"5";"6";"7";"8"},SUBSTITUTE(G14," ","")))))} -> 1 | U14: =IF(SUBSTITUTE(K14," ","") = SUBSTITUTE(G14," ",""), 1, 0) -> 1 | V14: {=SUMPRODUCT(--(ISNUMBER(SEARCH({"0";"1";"2";"3";"4";"5";"6";"7";"8"},SUBSTITUTE(K14," ",""))) * ISNUMBER(SEARCH({"0";"1";"2";"3";"4";"5";"6";"7";"8"},SUBSTITUTE(G14," ","")))))} -> 1 | W14: =IF(SUBSTITUTE(K14," ","") = SUBSTITUTE(C14," ",""), 1, 0) -> 1 | X14: {=SUMPRODUCT(--(ISNUMBER(SEARCH({"0";"1";"2";"3";"4";"5";"6";"7";"8"},SUBSTITUTE(K14," ",""))) * ISNUMBER(SEARCH({"0";"1";"2";"3";"4";"5";"6";"7";"8"},SUBSTITUTE(C14," ","")))))} -> 1 | Y14: =IF(SUBSTITUTE(K14," ","") = SUBSTITUTE(I14," ",""), 1, 0) -> 1 | Z14: {=SUMPRODUCT(--(ISNUMBER(SEARCH({"0";"1";"2";"3";"4";"5";"6";"7";"8"},SUBSTITUTE(K14," ",""))) * ISNUMBER(SEARCH({"0";"1";"2";"3";"4";"5";"6";"7";"8"},SUBSTITUTE(I14," ","")))))} -> 1 | AA14: =SUM(U2:U51) -> 21 | AB14: {=SUMPRODUCT(--(V2:V51>=1))} -> 27
A15: K0775 | B15: Knowledge of information management tools and techniques | C15: 0 | D15: 1 | G15: ='Sara Mappings'!C15 -> 0 | H15: =IF('Sara Mappings'!D15=0,"",'Sara Mappings'!D15) -> IT | I15: ='Valtteri Mappings'!C15 -> 0 | J15: =IF('Valtteri Mappings'!D15=0,"",'Valtteri Mappings'!D15) | K15: ='Paul Mappings'!C15 -> 0 | L15: =IF('Paul Mappings'!D15=0,"",'Paul Mappings'!D15) -> 5,1 also? | O15: =IF(SUBSTITUTE(G15," ","") = SUBSTITUTE(I15," ",""), 1, 0) -> 1 | P15: {=SUMPRODUCT(--(ISNUMBER(SEARCH({"0";"1";"2";"3";"4";"5";"6";"7";"8"},SUBSTITUTE(G15," ",""))) * ISNUMBER(SEARCH({"0";"1";"2";"3";"4";"5";"6";"7";"8"},SUBSTITUTE(I15," ","")))))} -> 1 | Q15: =IF(SUBSTITUTE(C15," ","") = SUBSTITUTE(I15," ",""), 1, 0) -> 1 | R15: {=SUMPRODUCT(--(ISNUMBER(SEARCH({"0";"1";"2";"3";"4";"5";"6";"7";"8"},SUBSTITUTE(C15," ",""))) * ISNUMBER(SEARCH({"0";"1";"2";"3";"4";"5";"6";"7";"8"},SUBSTITUTE(I15," ","")))))} -> 1 | S15: =IF(SUBSTITUTE(C15," ","") = SUBSTITUTE(G15," ",""), 1, 0) -> 1 | T15: {=SUMPRODUCT(--(ISNUMBER(SEARCH({"0";"1";"2";"3";"4";"5";"6";"7";"8"},SUBSTITUTE(C15," ",""))) * ISNUMBER(SEARCH({"0";"1";"2";"3";"4";"5";"6";"7";"8"},SUBSTITUTE(G15," ","")))))} -> 1 | U15: =IF(SUBSTITUTE(K15," ","") = SUBSTITUTE(G15," ",""), 1, 0) -> 1 | V15: {=SUMPRODUCT(--(ISNUMBER(SEARCH({"0";"1";"2";"3";"4";"5";"6";"7";"8"},SUBSTITUTE(K15," ",""))) * ISNUMBER(SEARCH({"0";"1";"2";"3";"4";"5";"6";"7";"8"},SUBSTITUTE(G15," ","")))))} -> 1 | W15: =IF(SUBSTITUTE(K15," ","") = SUBSTITUTE(C15," ",""), 1, 0) -> 1 | X15: {=SUMPRODUCT(--(ISNUMBER(SEARCH({"0";"1";"2";"3";"4";"5";"6";"7";"8"},SUBSTITUTE(K15," ",""))) * ISNUMBER(SEARCH({"0";"1";"2";"3";"4";"5";"6";"7";"8"},SUBSTITUTE(C15," ","")))))} -> 1 | Y15: =IF(SUBSTITUTE(K15," ","") = SUBSTITUTE(I15," ",""), 1, 0) -> 1 | Z15: {=SUMPRODUCT(--(ISNUMBER(SEARCH({"0";"1";"2";"3";"4";"5";"6";"7";"8"},SUBSTITUTE(K15," ",""))) * ISNUMBER(SEARCH({"0";"1";"2";"3";"4";"5";"6";"7";"8"},SUBSTITUTE(I15," ","")))))} -> 1 | AA15: =AA14/50 -> 0.42 | AB15: =AB14/50 -> 0.54
A16: K0776 | B16: Knowledge of collaboration tools and techniques | C16: 0 | D16: 1 | G16: ='Sara Mappings'!C16 -> 0 | H16: =IF('Sara Mappings'!D16=0,"",'Sara Mappings'!D16) -> Business and Law | I16: ='Valtteri Mappings'!C16 -> 0 | J16: =IF('Valtteri Mappings'!D16=0,"",'Valtteri Mappings'!D16) | K16: ='Paul Mappings'!C16 -> 0 | L16: =IF('Paul Mappings'!D16=0,"",'Paul Mappings'!D16) -> ? | O16: =IF(SUBSTITUTE(G16," ","") = SUBSTITUTE(I16," ",""), 1, 0) -> 1 | P16: {=SUMPRODUCT(--(ISNUMBER(SEARCH({"0";"1";"2";"3";"4";"5";"6";"7";"8"},SUBSTITUTE(G16," ",""))) * ISNUMBER(SEARCH({"0";"1";"2";"3";"4";"5";"6";"7";"8"},SUBSTITUTE(I16," ","")))))} -> 1 | Q16: =IF(SUBSTITUTE(C16," ","") = SUBSTITUTE(I16," ",""), 1, 0) -> 1 | R16: {=SUMPRODUCT(--(ISNUMBER(SEARCH({"0";"1";"2";"3";"4";"5";"6";"7";"8"},SUBSTITUTE(C16," ",""))) * ISNUMBER(SEARCH({"0";"1";"2";"3";"4";"5";"6";"7";"8"},SUBSTITUTE(I16," ","")))))} -> 1 | S16: =IF(SUBSTITUTE(C16," ","") = SUBSTITUTE(G16," ",""), 1, 0) -> 1 | T16: {=SUMPRODUCT(--(ISNUMBER(SEARCH({"0";"1";"2";"3";"4";"5";"6";"7";"8"},SUBSTITUTE(C16," ",""))) * ISNUMBER(SEARCH({"0";"1";"2";"3";"4";"5";"6";"7";"8"},SUBSTITUTE(G16," ","")))))} -> 1 | U16: =IF(SUBSTITUTE(K16," ","") = SUBSTITUTE(G16," ",""), 1, 0) -> 1 | V16: {=SUMPRODUCT(--(ISNUMBER(SEARCH({"0";"1";"2";"3";"4";"5";"6";"7";"8"},SUBSTITUTE(K16," ",""))) * ISNUMBER(SEARCH({"0";"1";"2";"3";"4";"5";"6";"7";"8"},SUBSTITUTE(G16," ","")))))} -> 1 | W16: =IF(SUBSTITUTE(K16," ","") = SUBSTITUTE(C16," ",""), 1, 0) -> 1 | X16: {=SUMPRODUCT(--(ISNUMBER(SEARCH({"0";"1";"2";"3";"4";"5";"6";"7";"8"},SUBSTITUTE(K16," ",""))) * ISNUMBER(SEARCH({"0";"1";"2";"3";"4";"5";"6";"7";"8"},SUBSTITUTE(C16," ","")))))} -> 1 | Y16: =IF(SUBSTITUTE(K16," ","") = SUBSTITUTE(I16," ",""), 1, 0) -> 1 | Z16: {=SUMPRODUCT(--(ISNUMBER(SEARCH({"0";"1";"2";"3";"4";"5";"6";"7";"8"},SUBSTITUTE(K16," ",""))) * ISNUMBER(SEARCH({"0";"1";"2";"3";"4";"5";"6";"7";"8"},SUBSTITUTE(I16," ","")))))} -> 1 | AA16: # of same P&V | AB16: # of intersected P&V
A17: K0798 | B17: Knowledge of program management principles and practices | C17: 0, 7 | D17: 1 | G17: ='Sara Mappings'!C17 -> 0 | H17: =IF('Sara Mappings'!D17=0,"",'Sara Mappings'!D17) | I17: ='Valtteri Mappings'!C17 -> 0 | J17: =IF('Valtteri Mappings'!D17=0,"",'Valtteri Mappings'!D17) | K17: ='Paul Mappings'!C17 -> 0 | L17: =IF('Paul Mappings'!D17=0,"",'Paul Mappings'!D17) -> educational program, computer program,...? | O17: =IF(SUBSTITUTE(G17," ","") = SUBSTITUTE(I17," ",""), 1, 0) -> 1 | P17: {=SUMPRODUCT(--(ISNUMBER(SEARCH({"0";"1";"2";"3";"4";"5";"6";"7";"8"},SUBSTITUTE(G17," ",""))) * ISNUMBER(SEARCH({"0";"1";"2";"3";"4";"5";"6";"7";"8"},SUBSTITUTE(I17," ","")))))} -> 1 | Q17: =IF(SUBSTITUTE(C17," ","") = SUBSTITUTE(I17," ",""), 1, 0) -> 0 | R17: {=SUMPRODUCT(--(ISNUMBER(SEARCH({"0";"1";"2";"3";"4";"5";"6";"7";"8"},SUBSTITUTE(C17," ",""))) * ISNUMBER(SEARCH({"0";"1";"2";"3";"4";"5";"6";"7";"8"},SUBSTITUTE(I17," ","")))))} -> 1 | S17: =IF(SUBSTITUTE(C17," ","") = SUBSTITUTE(G17," ",""), 1, 0) -> 0 | T17: {=SUMPRODUCT(--(ISNUMBER(SEARCH({"0";"1";"2";"3";"4";"5";"6";"7";"8"},SUBSTITUTE(C17," ",""))) * ISNUMBER(SEARCH({"0";"1";"2";"3";"4";"5";"6";"7";"8"},SUBSTITUTE(G17," ","")))))} -> 1 | U17: =IF(SUBSTITUTE(K17," ","") = SUBSTITUTE(G17," ",""), 1, 0) -> 1 | V17: {=SUMPRODUCT(--(ISNUMBER(SEARCH({"0";"1";"2";"3";"4";"5";"6";"7";"8"},SUBSTITUTE(K17," ",""))) * ISNUMBER(SEARCH({"0";"1";"2";"3";"4";"5";"6";"7";"8"},SUBSTITUTE(G17," ","")))))} -> 1 | W17: =IF(SUBSTITUTE(K17," ","") = SUBSTITUTE(C17," ",""), 1, 0) -> 0 | X17: {=SUMPRODUCT(--(ISNUMBER(SEARCH({"0";"1";"2";"3";"4";"5";"6";"7";"8"},SUBSTITUTE(K17," ",""))) * ISNUMBER(SEARCH({"0";"1";"2";"3";"4";"5";"6";"7";"8"},SUBSTITUTE(C17," ","")))))} -> 1 | Y17: =IF(SUBSTITUTE(K17," ","") = SUBSTITUTE(I17," ",""), 1, 0) -> 1 | Z17: {=SUMPRODUCT(--(ISNUMBER(SEARCH({"0";"1";"2";"3";"4";"5";"6";"7";"8"},SUBSTITUTE(K17," ",""))) * ISNUMBER(SEARCH({"0";"1";"2";"3";"4";"5";"6";"7";"8"},SUBSTITUTE(I17," ","")))))} -> 1 | AA17: =SUM(Y2:Y51) -> 20 | AB17: {=SUMPRODUCT(--(Z2:Z51>=1))} -> 28
A18: K0801 | B18: Knowledge of cognitive domain models and frameworks | C18: 0 | D18: 1 | G18: ='Sara Mappings'!C18 -> 0 | H18: =IF('Sara Mappings'!D18=0,"",'Sara Mappings'!D18) -> Pedagogy | I18: ='Valtteri Mappings'!C18 -> 0 | J18: =IF('Valtteri Mappings'!D18=0,"",'Valtteri Mappings'!D18) | K18: ='Paul Mappings'!C18 -> 0 | L18: =IF('Paul Mappings'!D18=0,"",'Paul Mappings'!D18) -> 6 human factors also? | O18: =IF(SUBSTITUTE(G18," ","") = SUBSTITUTE(I18," ",""), 1, 0) -> 1 | P18: {=SUMPRODUCT(--(ISNUMBER(SEARCH({"0";"1";"2";"3";"4";"5";"6";"7";"8"},SUBSTITUTE(G18," ",""))) * ISNUMBER(SEARCH({"0";"1";"2";"3";"4";"5";"6";"7";"8"},SUBSTITUTE(I18," ","")))))} -> 1 | Q18: =IF(SUBSTITUTE(C18," ","") = SUBSTITUTE(I18," ",""), 1, 0) -> 1 | R18: {=SUMPRODUCT(--(ISNUMBER(SEARCH({"0";"1";"2";"3";"4";"5";"6";"7";"8"},SUBSTITUTE(C18," ",""))) * ISNUMBER(SEARCH({"0";"1";"2";"3";"4";"5";"6";"7";"8"},SUBSTITUTE(I18," ","")))))} -> 1 | S18: =IF(SUBSTITUTE(C18," ","") = SUBSTITUTE(G18," ",""), 1, 0) -> 1 | T18: {=SUMPRODUCT(--(ISNUMBER(SEARCH({"0";"1";"2";"3";"4";"5";"6";"7";"8"},SUBSTITUTE(C18," ",""))) * ISNUMBER(SEARCH({"0";"1";"2";"3";"4";"5";"6";"7";"8"},SUBSTITUTE(G18," ","")))))} -> 1 | U18: =IF(SUBSTITUTE(K18," ","") = SUBSTITUTE(G18," ",""), 1, 0) -> 1 | V18: {=SUMPRODUCT(--(ISNUMBER(SEARCH({"0";"1";"2";"3";"4";"5";"6";"7";"8"},SUBSTITUTE(K18," ",""))) * ISNUMBER(SEARCH({"0";"1";"2";"3";"4";"5";"6";"7";"8"},SUBSTITUTE(G18," ","")))))} -> 1 | W18: =IF(SUBSTITUTE(K18," ","") = SUBSTITUTE(C18," ",""), 1, 0) -> 1 | X18: {=SUMPRODUCT(--(ISNUMBER(SEARCH({"0";"1";"2";"3";"4";"5";"6";"7";"8"},SUBSTITUTE(K18," ",""))) * ISNUMBER(SEARCH({"0";"1";"2";"3";"4";"5";"6";"7";"8"},SUBSTITUTE(C18," ","")))))} -> 1 | Y18: =IF(SUBSTITUTE(K18," ","") = SUBSTITUTE(I18," ",""), 1, 0) -> 1 | Z18: {=SUMPRODUCT(--(ISNUMBER(SEARCH({"0";"1";"2";"3";"4";"5";"6";"7";"8"},SUBSTITUTE(K18," ",""))) * ISNUMBER(SEARCH({"0";"1";"2";"3";"4";"5";"6";"7";"8"},SUBSTITUTE(I18," ","")))))} -> 1 | AA18: =AA17/50 -> 0.4 | AB18: =AB17/50 -> 0.56
A19: K0807 | B19: Knowledge of web mail tools and techniques | C19: 0 | D19: 1 | G19: ='Sara Mappings'!C19 -> 0 | H19: =IF('Sara Mappings'!D19=0,"",'Sara Mappings'!D19) -> CS | I19: ='Valtteri Mappings'!C19 -> 0 | J19: =IF('Valtteri Mappings'!D19=0,"",'Valtteri Mappings'!D19) | K19: ='Paul Mappings'!C19 -> 6 | L19: =IF('Paul Mappings'!D19=0,"",'Paul Mappings'!D19) -> Not web attacks or technical as I interpreted it | O19: =IF(SUBSTITUTE(G19," ","") = SUBSTITUTE(I19," ",""), 1, 0) -> 1 | P19: {=SUMPRODUCT(--(ISNUMBER(SEARCH({"0";"1";"2";"3";"4";"5";"6";"7";"8"},SUBSTITUTE(G19," ",""))) * ISNUMBER(SEARCH({"0";"1";"2";"3";"4";"5";"6";"7";"8"},SUBSTITUTE(I19," ","")))))} -> 1 | Q19: =IF(SUBSTITUTE(C19," ","") = SUBSTITUTE(I19," ",""), 1, 0) -> 1 | R19: {=SUMPRODUCT(--(ISNUMBER(SEARCH({"0";"1";"2";"3";"4";"5";"6";"7";"8"},SUBSTITUTE(C19," ",""))) * ISNUMBER(SEARCH({"0";"1";"2";"3";"4";"5";"6";"7";"8"},SUBSTITUTE(I19," ","")))))} -> 1 | S19: =IF(SUBSTITUTE(C19," ","") = SUBSTITUTE(G19," ",""), 1, 0) -> 1 | T19: {=SUMPRODUCT(--(ISNUMBER(SEARCH({"0";"1";"2";"3";"4";"5";"6";"7";"8"},SUBSTITUTE(C19," ",""))) * ISNUMBER(SEARCH({"0";"1";"2";"3";"4";"5";"6";"7";"8"},SUBSTITUTE(G19," ","")))))} -> 1 | U19: =IF(SUBSTITUTE(K19," ","") = SUBSTITUTE(G19," ",""), 1, 0) -> 0 | V19: {=SUMPRODUCT(--(ISNUMBER(SEARCH({"0";"1";"2";"3";"4";"5";"6";"7";"8"},SUBSTITUTE(K19," ",""))) * ISNUMBER(SEARCH({"0";"1";"2";"3";"4";"5";"6";"7";"8"},SUBSTITUTE(G19," ","")))))} -> 0 | W19: =IF(SUBSTITUTE(K19," ","") = SUBSTITUTE(C19," ",""), 1, 0) -> 0 | X19: {=SUMPRODUCT(--(ISNUMBER(SEARCH({"0";"1";"2";"3";"4";"5";"6";"7";"8"},SUBSTITUTE(K19," ",""))) * ISNUMBER(SEARCH({"0";"1";"2";"3";"4";"5";"6";"7";"8"},SUBSTITUTE(C19," ","")))))} -> 0 | Y19: =IF(SUBSTITUTE(K19," ","") = SUBSTITUTE(I19," ",""), 1, 0) -> 0 | Z19: {=SUMPRODUCT(--(ISNUMBER(SEARCH({"0";"1";"2";"3";"4";"5";"6";"7";"8"},SUBSTITUTE(K19," ",""))) * ISNUMBER(SEARCH({"0";"1";"2";"3";"4";"5";"6";"7";"8"},SUBSTITUTE(I19," ","")))))} -> 0
A20: K0814 | B20: Knowledge of secure coding tools and techniques | C20: 2 | D20: 1 | G20: ='Sara Mappings'!C20 -> 2 | H20: =IF('Sara Mappings'!D20=0,"",'Sara Mappings'!D20) | I20: ='Valtteri Mappings'!C20 -> 2 | J20: =IF('Valtteri Mappings'!D20=0,"",'Valtteri Mappings'!D20) | K20: ='Paul Mappings'!C20 -> 2 | L20: =IF('Paul Mappings'!D20=0,"",'Paul Mappings'!D20) | O20: =IF(SUBSTITUTE(G20," ","") = SUBSTITUTE(I20," ",""), 1, 0) -> 1 | P20: {=SUMPRODUCT(--(ISNUMBER(SEARCH({"0";"1";"2";"3";"4";"5";"6";"7";"8"},SUBSTITUTE(G20," ",""))) * ISNUMBER(SEARCH({"0";"1";"2";"3";"4";"5";"6";"7";"8"},SUBSTITUTE(I20," ","")))))} -> 1 | Q20: =IF(SUBSTITUTE(C20," ","") = SUBSTITUTE(I20," ",""), 1, 0) -> 1 | R20: {=SUMPRODUCT(--(ISNUMBER(SEARCH({"0";"1";"2";"3";"4";"5";"6";"7";"8"},SUBSTITUTE(C20," ",""))) * ISNUMBER(SEARCH({"0";"1";"2";"3";"4";"5";"6";"7";"8"},SUBSTITUTE(I20," ","")))))} -> 1 | S20: =IF(SUBSTITUTE(C20," ","") = SUBSTITUTE(G20," ",""), 1, 0) -> 1 | T20: {=SUMPRODUCT(--(ISNUMBER(SEARCH({"0";"1";"2";"3";"4";"5";"6";"7";"8"},SUBSTITUTE(C20," ",""))) * ISNUMBER(SEARCH({"0";"1";"2";"3";"4";"5";"6";"7";"8"},SUBSTITUTE(G20," ","")))))} -> 1 | U20: =IF(SUBSTITUTE(K20," ","") = SUBSTITUTE(G20," ",""), 1, 0) -> 1 | V20: {=SUMPRODUCT(--(ISNUMBER(SEARCH({"0";"1";"2";"3";"4";"5";"6";"7";"8"},SUBSTITUTE(K20," ",""))) * ISNUMBER(SEARCH({"0";"1";"2";"3";"4";"5";"6";"7";"8"},SUBSTITUTE(G20," ","")))))} -> 1 | W20: =IF(SUBSTITUTE(K20," ","") = SUBSTITUTE(C20," ",""), 1, 0) -> 1 | X20: {=SUMPRODUCT(--(ISNUMBER(SEARCH({"0";"1";"2";"3";"4";"5";"6";"7";"8"},SUBSTITUTE(K20," ",""))) * ISNUMBER(SEARCH({"0";"1";"2";"3";"4";"5";"6";"7";"8"},SUBSTITUTE(C20," ","")))))} -> 1 | Y20: =IF(SUBSTITUTE(K20," ","") = SUBSTITUTE(I20," ",""), 1, 0) -> 1 | Z20: {=SUMPRODUCT(--(ISNUMBER(SEARCH({"0";"1";"2";"3";"4";"5";"6";"7";"8"},SUBSTITUTE(K20," ",""))) * ISNUMBER(SEARCH({"0";"1";"2";"3";"4";"5";"6";"7";"8"},SUBSTITUTE(I20," ","")))))} -> 1
A21: K0822 | B21: Knowledge of risk tolerance principles and practices | C21: 7 | D21: 1 | G21: ='Sara Mappings'!C21 -> 7 | H21: =IF('Sara Mappings'!D21=0,"",'Sara Mappings'!D21) -> Risk Management | I21: ='Valtteri Mappings'!C21 -> 5 | J21: =IF('Valtteri Mappings'!D21=0,"",'Valtteri Mappings'!D21) | K21: ='Paul Mappings'!C21 -> 7 | L21: =IF('Paul Mappings'!D21=0,"",'Paul Mappings'!D21) -> many KAs relevant | O21: =IF(SUBSTITUTE(G21," ","") = SUBSTITUTE(I21," ",""), 1, 0) -> 0 | P21: {=SUMPRODUCT(--(ISNUMBER(SEARCH({"0";"1";"2";"3";"4";"5";"6";"7";"8"},SUBSTITUTE(G21," ",""))) * ISNUMBER(SEARCH({"0";"1";"2";"3";"4";"5";"6";"7";"8"},SUBSTITUTE(I21," ","")))))} -> 0 | Q21: =IF(SUBSTITUTE(C21," ","") = SUBSTITUTE(I21," ",""), 1, 0) -> 0 | R21: {=SUMPRODUCT(--(ISNUMBER(SEARCH({"0";"1";"2";"3";"4";"5";"6";"7";"8"},SUBSTITUTE(C21," ",""))) * ISNUMBER(SEARCH({"0";"1";"2";"3";"4";"5";"6";"7";"8"},SUBSTITUTE(I21," ","")))))} -> 0 | S21: =IF(SUBSTITUTE(C21," ","") = SUBSTITUTE(G21," ",""), 1, 0) -> 1 | T21: {=SUMPRODUCT(--(ISNUMBER(SEARCH({"0";"1";"2";"3";"4";"5";"6";"7";"8"},SUBSTITUTE(C21," ",""))) * ISNUMBER(SEARCH({"0";"1";"2";"3";"4";"5";"6";"7";"8"},SUBSTITUTE(G21," ","")))))} -> 1 | U21: =IF(SUBSTITUTE(K21," ","") = SUBSTITUTE(G21," ",""), 1, 0) -> 1 | V21: {=SUMPRODUCT(--(ISNUMBER(SEARCH({"0";"1";"2";"3";"4";"5";"6";"7";"8"},SUBSTITUTE(K21," ",""))) * ISNUMBER(SEARCH({"0";"1";"2";"3";"4";"5";"6";"7";"8"},SUBSTITUTE(G21," ","")))))} -> 1 | W21: =IF(SUBSTITUTE(K21," ","") = SUBSTITUTE(C21," ",""), 1, 0) -> 1 | X21: {=SUMPRODUCT(--(ISNUMBER(SEARCH({"0";"1";"2";"3";"4";"5";"6";"7";"8"},SUBSTITUTE(K21," ",""))) * ISNUMBER(SEARCH({"0";"1";"2";"3";"4";"5";"6";"7";"8"},SUBSTITUTE(C21," ","")))))} -> 1 | Y21: =IF(SUBSTITUTE(K21," ","") = SUBSTITUTE(I21," ",""), 1, 0) -> 0 | Z21: {=SUMPRODUCT(--(ISNUMBER(SEARCH({"0";"1";"2";"3";"4";"5";"6";"7";"8"},SUBSTITUTE(K21," ",""))) * ISNUMBER(SEARCH({"0";"1";"2";"3";"4";"5";"6";"7";"8"},SUBSTITUTE(I21," ","")))))} -> 0
A22: K0829 | B22: Knowledge of account creation policies and procedures | C22: 7 | D22: 0 | G22: ='Sara Mappings'!C22 -> 0 | H22: =IF('Sara Mappings'!D22=0,"",'Sara Mappings'!D22) -> Business and Law | I22: ='Valtteri Mappings'!C22 -> 0 | J22: =IF('Valtteri Mappings'!D22=0,"",'Valtteri Mappings'!D22) | K22: ='Paul Mappings'!C22 -> 5.6 | L22: =IF('Paul Mappings'!D22=0,"",'Paul Mappings'!D22) -> somewhat technical interpretation | O22: =IF(SUBSTITUTE(G22," ","") = SUBSTITUTE(I22," ",""), 1, 0) -> 1 | P22: {=SUMPRODUCT(--(ISNUMBER(SEARCH({"0";"1";"2";"3";"4";"5";"6";"7";"8"},SUBSTITUTE(G22," ",""))) * ISNUMBER(SEARCH({"0";"1";"2";"3";"4";"5";"6";"7";"8"},SUBSTITUTE(I22," ","")))))} -> 1 | Q22: =IF(SUBSTITUTE(C22," ","") = SUBSTITUTE(I22," ",""), 1, 0) -> 0 | R22: {=SUMPRODUCT(--(ISNUMBER(SEARCH({"0";"1";"2";"3";"4";"5";"6";"7";"8"},SUBSTITUTE(C22," ",""))) * ISNUMBER(SEARCH({"0";"1";"2";"3";"4";"5";"6";"7";"8"},SUBSTITUTE(I22," ","")))))} -> 0 | S22: =IF(SUBSTITUTE(C22," ","") = SUBSTITUTE(G22," ",""), 1, 0) -> 0 | T22: {=SUMPRODUCT(--(ISNUMBER(SEARCH({"0";"1";"2";"3";"4";"5";"6";"7";"8"},SUBSTITUTE(C22," ",""))) * ISNUMBER(SEARCH({"0";"1";"2";"3";"4";"5";"6";"7";"8"},SUBSTITUTE(G22," ","")))))} -> 0 | U22: =IF(SUBSTITUTE(K22," ","") = SUBSTITUTE(G22," ",""), 1, 0) -> 0 | V22: {=SUMPRODUCT(--(ISNUMBER(SEARCH({"0";"1";"2";"3";"4";"5";"6";"7";"8"},SUBSTITUTE(K22," ",""))) * ISNUMBER(SEARCH({"0";"1";"2";"3";"4";"5";"6";"7";"8"},SUBSTITUTE(G22," ","")))))} -> 0 | W22: =IF(SUBSTITUTE(K22," ","") = SUBSTITUTE(C22," ",""), 1, 0) -> 0 | X22: {=SUMPRODUCT(--(ISNUMBER(SEARCH({"0";"1";"2";"3";"4";"5";"6";"7";"8"},SUBSTITUTE(K22," ",""))) * ISNUMBER(SEARCH({"0";"1";"2";"3";"4";"5";"6";"7";"8"},SUBSTITUTE(C22," ","")))))} -> 0 | Y22: =IF(SUBSTITUTE(K22," ","") = SUBSTITUTE(I22," ",""), 1, 0) -> 0 | Z22: {=SUMPRODUCT(--(ISNUMBER(SEARCH({"0";"1";"2";"3";"4";"5";"6";"7";"8"},SUBSTITUTE(K22," ",""))) * ISNUMBER(SEARCH({"0";"1";"2";"3";"4";"5";"6";"7";"8"},SUBSTITUTE(I22," ","")))))} -> 0
A23: K0832 | B23: Knowledge of cyberattack characteristics | C23: 1, 5, 6, 7 | D23: 0 | E23: 1 | G23: ='Sara Mappings'!C23 -> 0 | H23: =IF('Sara Mappings'!D23=0,"",'Sara Mappings'!D23) -> Cyberspace Practice | I23: ='Valtteri Mappings'!C23 -> 5 | J23: =IF('Valtteri Mappings'!D23=0,"",'Valtteri Mappings'!D23) | K23: ='Paul Mappings'!C23 -> 8 | L23: =IF('Paul Mappings'!D23=0,"",'Paul Mappings'!D23) -> cybercrime | O23: =IF(SUBSTITUTE(G23," ","") = SUBSTITUTE(I23," ",""), 1, 0) -> 0 | P23: {=SUMPRODUCT(--(ISNUMBER(SEARCH({"0";"1";"2";"3";"4";"5";"6";"7";"8"},SUBSTITUTE(G23," ",""))) * ISNUMBER(SEARCH({"0";"1";"2";"3";"4";"5";"6";"7";"8"},SUBSTITUTE(I23," ","")))))} -> 0 | Q23: =IF(SUBSTITUTE(C23," ","") = SUBSTITUTE(I23," ",""), 1, 0) -> 0 | R23: {=SUMPRODUCT(--(ISNUMBER(SEARCH({"0";"1";"2";"3";"4";"5";"6";"7";"8"},SUBSTITUTE(C23," ",""))) * ISNUMBER(SEARCH({"0";"1";"2";"3";"4";"5";"6";"7";"8"},SUBSTITUTE(I23," ","")))))} -> 1 | S23: =IF(SUBSTITUTE(C23," ","") = SUBSTITUTE(G23," ",""), 1, 0) -> 0 | T23: {=SUMPRODUCT(--(ISNUMBER(SEARCH({"0";"1";"2";"3";"4";"5";"6";"7";"8"},SUBSTITUTE(C23," ",""))) * ISNUMBER(SEARCH({"0";"1";"2";"3";"4";"5";"6";"7";"8"},SUBSTITUTE(G23," ","")))))} -> 0 | U23: =IF(SUBSTITUTE(K23," ","") = SUBSTITUTE(G23," ",""), 1, 0) -> 0 | V23: {=SUMPRODUCT(--(ISNUMBER(SEARCH({"0";"1";"2";"3";"4";"5";"6";"7";"8"},SUBSTITUTE(K23," ",""))) * ISNUMBER(SEARCH({"0";"1";"2";"3";"4";"5";"6";"7";"8"},SUBSTITUTE(G23," ","")))))} -> 0 | W23: =IF(SUBSTITUTE(K23," ","") = SUBSTITUTE(C23," ",""), 1, 0) -> 0 | X23: {=SUMPRODUCT(--(ISNUMBER(SEARCH({"0";"1";"2";"3";"4";"5";"6";"7";"8"},SUBSTITUTE(K23," ",""))) * ISNUMBER(SEARCH({"0";"1";"2";"3";"4";"5";"6";"7";"8"},SUBSTITUTE(C23," ","")))))} -> 0 | Y23: =IF(SUBSTITUTE(K23," ","") = SUBSTITUTE(I23," ",""), 1, 0) -> 0 | Z23: {=SUMPRODUCT(--(ISNUMBER(SEARCH({"0";"1";"2";"3";"4";"5";"6";"7";"8"},SUBSTITUTE(K23," ",""))) * ISNUMBER(SEARCH({"0";"1";"2";"3";"4";"5";"6";"7";"8"},SUBSTITUTE(I23," ","")))))} -> 0
A24: K0844 | B24: Knowledge of cyberattack stages | C24: 5, 7 | D24: 0 | E24: 1 | G24: ='Sara Mappings'!C24 -> 0 | H24: =IF('Sara Mappings'!D24=0,"",'Sara Mappings'!D24) -> Cyberspace Practice | I24: ='Valtteri Mappings'!C24 -> 5 | J24: =IF('Valtteri Mappings'!D24=0,"",'Valtteri Mappings'!D24) | K24: ='Paul Mappings'!C24 -> 8 | L24: =IF('Paul Mappings'!D24=0,"",'Paul Mappings'!D24) -> cybercrime | O24: =IF(SUBSTITUTE(G24," ","") = SUBSTITUTE(I24," ",""), 1, 0) -> 0 | P24: {=SUMPRODUCT(--(ISNUMBER(SEARCH({"0";"1";"2";"3";"4";"5";"6";"7";"8"},SUBSTITUTE(G24," ",""))) * ISNUMBER(SEARCH({"0";"1";"2";"3";"4";"5";"6";"7";"8"},SUBSTITUTE(I24," ","")))))} -> 0 | Q24: =IF(SUBSTITUTE(C24," ","") = SUBSTITUTE(I24," ",""), 1, 0) -> 0 | R24: {=SUMPRODUCT(--(ISNUMBER(SEARCH({"0";"1";"2";"3";"4";"5";"6";"7";"8"},SUBSTITUTE(C24," ",""))) * ISNUMBER(SEARCH({"0";"1";"2";"3";"4";"5";"6";"7";"8"},SUBSTITUTE(I24," ","")))))} -> 1 | S24: =IF(SUBSTITUTE(C24," ","") = SUBSTITUTE(G24," ",""), 1, 0) -> 0 | T24: {=SUMPRODUCT(--(ISNUMBER(SEARCH({"0";"1";"2";"3";"4";"5";"6";"7";"8"},SUBSTITUTE(C24," ",""))) * ISNUMBER(SEARCH({"0";"1";"2";"3";"4";"5";"6";"7";"8"},SUBSTITUTE(G24," ","")))))} -> 0 | U24: =IF(SUBSTITUTE(K24," ","") = SUBSTITUTE(G24," ",""), 1, 0) -> 0 | V24: {=SUMPRODUCT(--(ISNUMBER(SEARCH({"0";"1";"2";"3";"4";"5";"6";"7";"8"},SUBSTITUTE(K24," ",""))) * ISNUMBER(SEARCH({"0";"1";"2";"3";"4";"5";"6";"7";"8"},SUBSTITUTE(G24," ","")))))} -> 0 | W24: =IF(SUBSTITUTE(K24," ","") = SUBSTITUTE(C24," ",""), 1, 0) -> 0 | X24: {=SUMPRODUCT(--(ISNUMBER(SEARCH({"0";"1";"2";"3";"4";"5";"6";"7";"8"},SUBSTITUTE(K24," ",""))) * ISNUMBER(SEARCH({"0";"1";"2";"3";"4";"5";"6";"7";"8"},SUBSTITUTE(C24," ","")))))} -> 0 | Y24: =IF(SUBSTITUTE(K24," ","") = SUBSTITUTE(I24," ",""), 1, 0) -> 0 | Z24: {=SUMPRODUCT(--(ISNUMBER(SEARCH({"0";"1";"2";"3";"4";"5";"6";"7";"8"},SUBSTITUTE(K24," ",""))) * ISNUMBER(SEARCH({"0";"1";"2";"3";"4";"5";"6";"7";"8"},SUBSTITUTE(I24," ","")))))} -> 0
A25: K0845 | B25: Knowledge of cyber intrusion activity phases | C25: 5, 7 | D25: 1 | G25: ='Sara Mappings'!C25 -> 4 | H25: =IF('Sara Mappings'!D25=0,"",'Sara Mappings'!D25) -> Network Defense | I25: ='Valtteri Mappings'!C25 -> 5 | J25: =IF('Valtteri Mappings'!D25=0,"",'Valtteri Mappings'!D25) | K25: ='Paul Mappings'!C25 -> 5 | L25: =IF('Paul Mappings'!D25=0,"",'Paul Mappings'!D25) -> IDS | O25: =IF(SUBSTITUTE(G25," ","") = SUBSTITUTE(I25," ",""), 1, 0) -> 0 | P25: {=SUMPRODUCT(--(ISNUMBER(SEARCH({"0";"1";"2";"3";"4";"5";"6";"7";"8"},SUBSTITUTE(G25," ",""))) * ISNUMBER(SEARCH({"0";"1";"2";"3";"4";"5";"6";"7";"8"},SUBSTITUTE(I25," ","")))))} -> 0 | Q25: =IF(SUBSTITUTE(C25," ","") = SUBSTITUTE(I25," ",""), 1, 0) -> 0 | R25: {=SUMPRODUCT(--(ISNUMBER(SEARCH({"0";"1";"2";"3";"4";"5";"6";"7";"8"},SUBSTITUTE(C25," ",""))) * ISNUMBER(SEARCH({"0";"1";"2";"3";"4";"5";"6";"7";"8"},SUBSTITUTE(I25," ","")))))} -> 1 | S25: =IF(SUBSTITUTE(C25," ","") = SUBSTITUTE(G25," ",""), 1, 0) -> 0 | T25: {=SUMPRODUCT(--(ISNUMBER(SEARCH({"0";"1";"2";"3";"4";"5";"6";"7";"8"},SUBSTITUTE(C25," ",""))) * ISNUMBER(SEARCH({"0";"1";"2";"3";"4";"5";"6";"7";"8"},SUBSTITUTE(G25," ","")))))} -> 0 | U25: =IF(SUBSTITUTE(K25," ","") = SUBSTITUTE(G25," ",""), 1, 0) -> 0 | V25: {=SUMPRODUCT(--(ISNUMBER(SEARCH({"0";"1";"2";"3";"4";"5";"6";"7";"8"},SUBSTITUTE(K25," ",""))) * ISNUMBER(SEARCH({"0";"1";"2";"3";"4";"5";"6";"7";"8"},SUBSTITUTE(G25," ","")))))} -> 0 | W25: =IF(SUBSTITUTE(K25," ","") = SUBSTITUTE(C25," ",""), 1, 0) -> 0 | X25: {=SUMPRODUCT(--(ISNUMBER(SEARCH({"0";"1";"2";"3";"4";"5";"6";"7";"8"},SUBSTITUTE(K25," ",""))) * ISNUMBER(SEARCH({"0";"1";"2";"3";"4";"5";"6";"7";"8"},SUBSTITUTE(C25," ","")))))} -> 1 | Y25: =IF(SUBSTITUTE(K25," ","") = SUBSTITUTE(I25," ",""), 1, 0) -> 1 | Z25: {=SUMPRODUCT(--(ISNUMBER(SEARCH({"0";"1";"2";"3";"4";"5";"6";"7";"8"},SUBSTITUTE(K25," ",""))) * ISNUMBER(SEARCH({"0";"1";"2";"3";"4";"5";"6";"7";"8"},SUBSTITUTE(I25," ","")))))} -> 1
A26: K0901 | B26: Knowledge of crisis management tools and techniques | C26: 7, 8 | D26: 1 | G26: ='Sara Mappings'!C26 -> 7 | H26: =IF('Sara Mappings'!D26=0,"",'Sara Mappings'!D26) -> Risk Management | I26: ='Valtteri Mappings'!C26 -> 7 | J26: =IF('Valtteri Mappings'!D26=0,"",'Valtteri Mappings'!D26) | K26: ='Paul Mappings'!C26 -> 7.6 | L26: =IF('Paul Mappings'!D26=0,"",'Paul Mappings'!D26) | O26: =IF(SUBSTITUTE(G26," ","") = SUBSTITUTE(I26," ",""), 1, 0) -> 1 | P26: {=SUMPRODUCT(--(ISNUMBER(SEARCH({"0";"1";"2";"3";"4";"5";"6";"7";"8"},SUBSTITUTE(G26," ",""))) * ISNUMBER(SEARCH({"0";"1";"2";"3";"4";"5";"6";"7";"8"},SUBSTITUTE(I26," ","")))))} -> 1 | Q26: =IF(SUBSTITUTE(C26," ","") = SUBSTITUTE(I26," ",""), 1, 0) -> 0 | R26: {=SUMPRODUCT(--(ISNUMBER(SEARCH({"0";"1";"2";"3";"4";"5";"6";"7";"8"},SUBSTITUTE(C26," ",""))) * ISNUMBER(SEARCH({"0";"1";"2";"3";"4";"5";"6";"7";"8"},SUBSTITUTE(I26," ","")))))} -> 1 | S26: =IF(SUBSTITUTE(C26," ","") = SUBSTITUTE(G26," ",""), 1, 0) -> 0 | T26: {=SUMPRODUCT(--(ISNUMBER(SEARCH({"0";"1";"2";"3";"4";"5";"6";"7";"8"},SUBSTITUTE(C26," ",""))) * ISNUMBER(SEARCH({"0";"1";"2";"3";"4";"5";"6";"7";"8"},SUBSTITUTE(G26," ","")))))} -> 1 | U26: =IF(SUBSTITUTE(K26," ","") = SUBSTITUTE(G26," ",""), 1, 0) -> 0 | V26: {=SUMPRODUCT(--(ISNUMBER(SEARCH({"0";"1";"2";"3";"4";"5";"6";"7";"8"},SUBSTITUTE(K26," ",""))) * ISNUMBER(SEARCH({"0";"1";"2";"3";"4";"5";"6";"7";"8"},SUBSTITUTE(G26," ","")))))} -> 1 | W26: =IF(SUBSTITUTE(K26," ","") = SUBSTITUTE(C26," ",""), 1, 0) -> 0 | X26: {=SUMPRODUCT(--(ISNUMBER(SEARCH({"0";"1";"2";"3";"4";"5";"6";"7";"8"},SUBSTITUTE(K26," ",""))) * ISNUMBER(SEARCH({"0";"1";"2";"3";"4";"5";"6";"7";"8"},SUBSTITUTE(C26," ","")))))} -> 1 | Y26: =IF(SUBSTITUTE(K26," ","") = SUBSTITUTE(I26," ",""), 1, 0) -> 0 | Z26: {=SUMPRODUCT(--(ISNUMBER(SEARCH({"0";"1";"2";"3";"4";"5";"6";"7";"8"},SUBSTITUTE(K26," ",""))) * ISNUMBER(SEARCH({"0";"1";"2";"3";"4";"5";"6";"7";"8"},SUBSTITUTE(I26," ","")))))} -> 1
A27: K0941 | B27: Knowledge of data concealment tools and techniques | C27: 1, 5 | D27: 1 | G27: ='Sara Mappings'!C27 -> 0 | H27: =IF('Sara Mappings'!D27=0,"",'Sara Mappings'!D27) -> Cyberspace Practice | I27: ='Valtteri Mappings'!C27 -> 1 | J27: =IF('Valtteri Mappings'!D27=0,"",'Valtteri Mappings'!D27) | K27: ='Paul Mappings'!C27 -> 1 | L27: =IF('Paul Mappings'!D27=0,"",'Paul Mappings'!D27) | O27: =IF(SUBSTITUTE(G27," ","") = SUBSTITUTE(I27," ",""), 1, 0) -> 0 | P27: {=SUMPRODUCT(--(ISNUMBER(SEARCH({"0";"1";"2";"3";"4";"5";"6";"7";"8"},SUBSTITUTE(G27," ",""))) * ISNUMBER(SEARCH({"0";"1";"2";"3";"4";"5";"6";"7";"8"},SUBSTITUTE(I27," ","")))))} -> 0 | Q27: =IF(SUBSTITUTE(C27," ","") = SUBSTITUTE(I27," ",""), 1, 0) -> 0 | R27: {=SUMPRODUCT(--(ISNUMBER(SEARCH({"0";"1";"2";"3";"4";"5";"6";"7";"8"},SUBSTITUTE(C27," ",""))) * ISNUMBER(SEARCH({"0";"1";"2";"3";"4";"5";"6";"7";"8"},SUBSTITUTE(I27," ","")))))} -> 1 | S27: =IF(SUBSTITUTE(C27," ","") = SUBSTITUTE(G27," ",""), 1, 0) -> 0 | T27: {=SUMPRODUCT(--(ISNUMBER(SEARCH({"0";"1";"2";"3";"4";"5";"6";"7";"8"},SUBSTITUTE(C27," ",""))) * ISNUMBER(SEARCH({"0";"1";"2";"3";"4";"5";"6";"7";"8"},SUBSTITUTE(G27," ","")))))} -> 0 | U27: =IF(SUBSTITUTE(K27," ","") = SUBSTITUTE(G27," ",""), 1, 0) -> 0 | V27: {=SUMPRODUCT(--(ISNUMBER(SEARCH({"0";"1";"2";"3";"4";"5";"6";"7";"8"},SUBSTITUTE(K27," ",""))) * ISNUMBER(SEARCH({"0";"1";"2";"3";"4";"5";"6";"7";"8"},SUBSTITUTE(G27," ","")))))} -> 0 | W27: =IF(SUBSTITUTE(K27," ","") = SUBSTITUTE(C27," ",""), 1, 0) -> 0 | X27: {=SUMPRODUCT(--(ISNUMBER(SEARCH({"0";"1";"2";"3";"4";"5";"6";"7";"8"},SUBSTITUTE(K27," ",""))) * ISNUMBER(SEARCH({"0";"1";"2";"3";"4";"5";"6";"7";"8"},SUBSTITUTE(C27," ","")))))} -> 1 | Y27: =IF(SUBSTITUTE(K27," ","") = SUBSTITUTE(I27," ",""), 1, 0) -> 1 | Z27: {=SUMPRODUCT(--(ISNUMBER(SEARCH({"0";"1";"2";"3";"4";"5";"6";"7";"8"},SUBSTITUTE(K27," ",""))) * ISNUMBER(SEARCH({"0";"1";"2";"3";"4";"5";"6";"7";"8"},SUBSTITUTE(I27," ","")))))} -> 1
A28: K0948 | B28: Knowledge of embedded systems and software | C28: 0, 3, 5 | D28: 1 | G28: ='Sara Mappings'!C28 -> 0 | H28: =IF('Sara Mappings'!D28=0,"",'Sara Mappings'!D28) -> cs | I28: ='Valtteri Mappings'!C28 -> 0 | J28: =IF('Valtteri Mappings'!D28=0,"",'Valtteri Mappings'!D28) | K28: ='Paul Mappings'!C28 -> 2.5 | L28: =IF('Paul Mappings'!D28=0,"",'Paul Mappings'!D28) | O28: =IF(SUBSTITUTE(G28," ","") = SUBSTITUTE(I28," ",""), 1, 0) -> 1 | P28: {=SUMPRODUCT(--(ISNUMBER(SEARCH({"0";"1";"2";"3";"4";"5";"6";"7";"8"},SUBSTITUTE(G28," ",""))) * ISNUMBER(SEARCH({"0";"1";"2";"3";"4";"5";"6";"7";"8"},SUBSTITUTE(I28," ","")))))} -> 1 | Q28: =IF(SUBSTITUTE(C28," ","") = SUBSTITUTE(I28," ",""), 1, 0) -> 0 | R28: {=SUMPRODUCT(--(ISNUMBER(SEARCH({"0";"1";"2";"3";"4";"5";"6";"7";"8"},SUBSTITUTE(C28," ",""))) * ISNUMBER(SEARCH({"0";"1";"2";"3";"4";"5";"6";"7";"8"},SUBSTITUTE(I28," ","")))))} -> 1 | S28: =IF(SUBSTITUTE(C28," ","") = SUBSTITUTE(G28," ",""), 1, 0) -> 0 | T28: {=SUMPRODUCT(--(ISNUMBER(SEARCH({"0";"1";"2";"3";"4";"5";"6";"7";"8"},SUBSTITUTE(C28," ",""))) * ISNUMBER(SEARCH({"0";"1";"2";"3";"4";"5";"6";"7";"8"},SUBSTITUTE(G28," ","")))))} -> 1 | U28: =IF(SUBSTITUTE(K28," ","") = SUBSTITUTE(G28," ",""), 1, 0) -> 0 | V28: {=SUMPRODUCT(--(ISNUMBER(SEARCH({"0";"1";"2";"3";"4";"5";"6";"7";"8"},SUBSTITUTE(K28," ",""))) * ISNUMBER(SEARCH({"0";"1";"2";"3";"4";"5";"6";"7";"8"},SUBSTITUTE(G28," ","")))))} -> 0 | W28: =IF(SUBSTITUTE(K28," ","") = SUBSTITUTE(C28," ",""), 1, 0) -> 0 | X28: {=SUMPRODUCT(--(ISNUMBER(SEARCH({"0";"1";"2";"3";"4";"5";"6";"7";"8"},SUBSTITUTE(K28," ",""))) * ISNUMBER(SEARCH({"0";"1";"2";"3";"4";"5";"6";"7";"8"},SUBSTITUTE(C28," ","")))))} -> 1 | Y28: =IF(SUBSTITUTE(K28," ","") = SUBSTITUTE(I28," ",""), 1, 0) -> 0 | Z28: {=SUMPRODUCT(--(ISNUMBER(SEARCH({"0";"1";"2";"3";"4";"5";"6";"7";"8"},SUBSTITUTE(K28," ",""))) * ISNUMBER(SEARCH({"0";"1";"2";"3";"4";"5";"6";"7";"8"},SUBSTITUTE(I28," ","")))))} -> 0
A29: K0980 | B29: Knowledge of intelligence collection sources | C29: 0 | D29: 1 | G29: ='Sara Mappings'!C29 -> 0 | H29: =IF('Sara Mappings'!D29=0,"",'Sara Mappings'!D29) -> Cyberspace Practice | I29: ='Valtteri Mappings'!C29 -> 0 | J29: =IF('Valtteri Mappings'!D29=0,"",'Valtteri Mappings'!D29) -> Intelligence | K29: ='Paul Mappings'!C29 -> 7 | L29: =IF('Paul Mappings'!D29=0,"",'Paul Mappings'!D29) | O29: =IF(SUBSTITUTE(G29," ","") = SUBSTITUTE(I29," ",""), 1, 0) -> 1 | P29: {=SUMPRODUCT(--(ISNUMBER(SEARCH({"0";"1";"2";"3";"4";"5";"6";"7";"8"},SUBSTITUTE(G29," ",""))) * ISNUMBER(SEARCH({"0";"1";"2";"3";"4";"5";"6";"7";"8"},SUBSTITUTE(I29," ","")))))} -> 1 | Q29: =IF(SUBSTITUTE(C29," ","") = SUBSTITUTE(I29," ",""), 1, 0) -> 1 | R29: {=SUMPRODUCT(--(ISNUMBER(SEARCH({"0";"1";"2";"3";"4";"5";"6";"7";"8"},SUBSTITUTE(C29," ",""))) * ISNUMBER(SEARCH({"0";"1";"2";"3";"4";"5";"6";"7";"8"},SUBSTITUTE(I29," ","")))))} -> 1 | S29: =IF(SUBSTITUTE(C29," ","") = SUBSTITUTE(G29," ",""), 1, 0) -> 1 | T29: {=SUMPRODUCT(--(ISNUMBER(SEARCH({"0";"1";"2";"3";"4";"5";"6";"7";"8"},SUBSTITUTE(C29," ",""))) * ISNUMBER(SEARCH({"0";"1";"2";"3";"4";"5";"6";"7";"8"},SUBSTITUTE(G29," ","")))))} -> 1 | U29: =IF(SUBSTITUTE(K29," ","") = SUBSTITUTE(G29," ",""), 1, 0) -> 0 | V29: {=SUMPRODUCT(--(ISNUMBER(SEARCH({"0";"1";"2";"3";"4";"5";"6";"7";"8"},SUBSTITUTE(K29," ",""))) * ISNUMBER(SEARCH({"0";"1";"2";"3";"4";"5";"6";"7";"8"},SUBSTITUTE(G29," ","")))))} -> 0 | W29: =IF(SUBSTITUTE(K29," ","") = SUBSTITUTE(C29," ",""), 1, 0) -> 0 | X29: {=SUMPRODUCT(--(ISNUMBER(SEARCH({"0";"1";"2";"3";"4";"5";"6";"7";"8"},SUBSTITUTE(K29," ",""))) * ISNUMBER(SEARCH({"0";"1";"2";"3";"4";"5";"6";"7";"8"},SUBSTITUTE(C29," ","")))))} -> 0 | Y29: =IF(SUBSTITUTE(K29," ","") = SUBSTITUTE(I29," ",""), 1, 0) -> 0 | Z29: {=SUMPRODUCT(--(ISNUMBER(SEARCH({"0";"1";"2";"3";"4";"5";"6";"7";"8"},SUBSTITUTE(K29," ",""))) * ISNUMBER(SEARCH({"0";"1";"2";"3";"4";"5";"6";"7";"8"},SUBSTITUTE(I29," ","")))))} -> 0
A30: K0986 | B30: Knowledge of target selection criticality factors | C30: 0, 7 | D30: 1 | G30: ='Sara Mappings'!C30 -> 0 | H30: =IF('Sara Mappings'!D30=0,"",'Sara Mappings'!D30) -> Cyberspace Practice | I30: ='Valtteri Mappings'!C30 -> 7 | J30: =IF('Valtteri Mappings'!D30=0,"",'Valtteri Mappings'!D30) | K30: ='Paul Mappings'!C30 -> 7 | L30: =IF('Paul Mappings'!D30=0,"",'Paul Mappings'!D30) -> incident management | O30: =IF(SUBSTITUTE(G30," ","") = SUBSTITUTE(I30," ",""), 1, 0) -> 0 | P30: {=SUMPRODUCT(--(ISNUMBER(SEARCH({"0";"1";"2";"3";"4";"5";"6";"7";"8"},SUBSTITUTE(G30," ",""))) * ISNUMBER(SEARCH({"0";"1";"2";"3";"4";"5";"6";"7";"8"},SUBSTITUTE(I30," ","")))))} -> 0 | Q30: =IF(SUBSTITUTE(C30," ","") = SUBSTITUTE(I30," ",""), 1, 0) -> 0 | R30: {=SUMPRODUCT(--(ISNUMBER(SEARCH({"0";"1";"2";"3";"4";"5";"6";"7";"8"},SUBSTITUTE(C30," ",""))) * ISNUMBER(SEARCH({"0";"1";"2";"3";"4";"5";"6";"7";"8"},SUBSTITUTE(I30," ","")))))} -> 1 | S30: =IF(SUBSTITUTE(C30," ","") = SUBSTITUTE(G30," ",""), 1, 0) -> 0 | T30: {=SUMPRODUCT(--(ISNUMBER(SEARCH({"0";"1";"2";"3";"4";"5";"6";"7";"8"},SUBSTITUTE(C30," ",""))) * ISNUMBER(SEARCH({"0";"1";"2";"3";"4";"5";"6";"7";"8"},SUBSTITUTE(G30," ","")))))} -> 1 | U30: =IF(SUBSTITUTE(K30," ","") = SUBSTITUTE(G30," ",""), 1, 0) -> 0 | V30: {=SUMPRODUCT(--(ISNUMBER(SEARCH({"0";"1";"2";"3";"4";"5";"6";"7";"8"},SUBSTITUTE(K30," ",""))) * ISNUMBER(SEARCH({"0";"1";"2";"3";"4";"5";"6";"7";"8"},SUBSTITUTE(G30," ","")))))} -> 0 | W30: =IF(SUBSTITUTE(K30," ","") = SUBSTITUTE(C30," ",""), 1, 0) -> 0 | X30: {=SUMPRODUCT(--(ISNUMBER(SEARCH({"0";"1";"2";"3";"4";"5";"6";"7";"8"},SUBSTITUTE(K30," ",""))) * ISNUMBER(SEARCH({"0";"1";"2";"3";"4";"5";"6";"7";"8"},SUBSTITUTE(C30," ","")))))} -> 1 | Y30: =IF(SUBSTITUTE(K30," ","") = SUBSTITUTE(I30," ",""), 1, 0) -> 1 | Z30: {=SUMPRODUCT(--(ISNUMBER(SEARCH({"0";"1";"2";"3";"4";"5";"6";"7";"8"},SUBSTITUTE(K30," ",""))) * ISNUMBER(SEARCH({"0";"1";"2";"3";"4";"5";"6";"7";"8"},SUBSTITUTE(I30," ","")))))} -> 1
